2022-08-18 01:30:39 ERROR 'str' object has no attribute '_meta'
Traceback (most recent call last):
  File "/home/quang/Desktop/Python/blog-django/venv/lib/python3.8/site-packages/django/core/handlers/base.py", line 197, in _get_response
    response = wrapped_callback(request, *callback_args, **callback_kwargs)
  File "/usr/lib/python3.8/contextlib.py", line 75, in inner
    return func(*args, **kwds)
  File "/home/quang/Desktop/Python/blog-django/venv/lib/python3.8/site-packages/django/views/decorators/csrf.py", line 54, in wrapped_view
    return view_func(*args, **kwargs)
  File "/home/quang/Desktop/Python/blog-django/venv/lib/python3.8/site-packages/rest_framework/viewsets.py", line 125, in view
    return self.dispatch(request, *args, **kwargs)
  File "/home/quang/Desktop/Python/blog-django/venv/lib/python3.8/site-packages/rest_framework/views.py", line 509, in dispatch
    response = self.handle_exception(exc)
  File "/home/quang/Desktop/Python/blog-django/venv/lib/python3.8/site-packages/rest_framework/views.py", line 469, in handle_exception
    self.raise_uncaught_exception(exc)
  File "/home/quang/Desktop/Python/blog-django/venv/lib/python3.8/site-packages/rest_framework/views.py", line 480, in raise_uncaught_exception
    raise exc
  File "/home/quang/Desktop/Python/blog-django/venv/lib/python3.8/site-packages/rest_framework/views.py", line 506, in dispatch
    response = handler(request, *args, **kwargs)
  File "/home/quang/Desktop/Python/blog-django/venv/lib/python3.8/site-packages/rest_framework/mixins.py", line 43, in list
    return self.get_paginated_response(serializer.data)
  File "/home/quang/Desktop/Python/blog-django/venv/lib/python3.8/site-packages/rest_framework/serializers.py", line 768, in data
    ret = super().data
  File "/home/quang/Desktop/Python/blog-django/venv/lib/python3.8/site-packages/rest_framework/serializers.py", line 253, in data
    self._data = self.to_representation(self.instance)
  File "/home/quang/Desktop/Python/blog-django/venv/lib/python3.8/site-packages/rest_framework/serializers.py", line 686, in to_representation
    return [
  File "/home/quang/Desktop/Python/blog-django/venv/lib/python3.8/site-packages/rest_framework/serializers.py", line 687, in <listcomp>
    self.child.to_representation(item) for item in iterable
  File "/home/quang/Desktop/Python/blog-django/venv/lib/python3.8/site-packages/rest_framework/serializers.py", line 507, in to_representation
    for field in fields:
  File "/home/quang/Desktop/Python/blog-django/venv/lib/python3.8/site-packages/rest_framework/serializers.py", line 368, in _readable_fields
    for field in self.fields.values():
  File "/home/quang/Desktop/Python/blog-django/venv/lib/python3.8/site-packages/django/utils/functional.py", line 57, in __get__
    res = instance.__dict__[self.name] = self.func(instance)
  File "/home/quang/Desktop/Python/blog-django/venv/lib/python3.8/site-packages/rest_framework/serializers.py", line 356, in fields
    for key, value in self.get_fields().items():
  File "/home/quang/Desktop/Python/blog-django/venv/lib/python3.8/site-packages/rest_framework/serializers.py", line 1051, in get_fields
    info = model_meta.get_field_info(model)
  File "/home/quang/Desktop/Python/blog-django/venv/lib/python3.8/site-packages/rest_framework/utils/model_meta.py", line 35, in get_field_info
    opts = model._meta.concrete_model._meta
AttributeError: 'str' object has no attribute '_meta'
2022-08-18 01:33:20 ERROR 'str' object has no attribute '_meta'
Traceback (most recent call last):
  File "/home/quang/Desktop/Python/blog-django/venv/lib/python3.8/site-packages/django/core/handlers/base.py", line 197, in _get_response
    response = wrapped_callback(request, *callback_args, **callback_kwargs)
  File "/usr/lib/python3.8/contextlib.py", line 75, in inner
    return func(*args, **kwds)
  File "/home/quang/Desktop/Python/blog-django/venv/lib/python3.8/site-packages/django/views/decorators/csrf.py", line 54, in wrapped_view
    return view_func(*args, **kwargs)
  File "/home/quang/Desktop/Python/blog-django/venv/lib/python3.8/site-packages/rest_framework/viewsets.py", line 125, in view
    return self.dispatch(request, *args, **kwargs)
  File "/home/quang/Desktop/Python/blog-django/venv/lib/python3.8/site-packages/rest_framework/views.py", line 509, in dispatch
    response = self.handle_exception(exc)
  File "/home/quang/Desktop/Python/blog-django/venv/lib/python3.8/site-packages/rest_framework/views.py", line 469, in handle_exception
    self.raise_uncaught_exception(exc)
  File "/home/quang/Desktop/Python/blog-django/venv/lib/python3.8/site-packages/rest_framework/views.py", line 480, in raise_uncaught_exception
    raise exc
  File "/home/quang/Desktop/Python/blog-django/venv/lib/python3.8/site-packages/rest_framework/views.py", line 506, in dispatch
    response = handler(request, *args, **kwargs)
  File "/home/quang/Desktop/Python/blog-django/venv/lib/python3.8/site-packages/rest_framework/mixins.py", line 43, in list
    return self.get_paginated_response(serializer.data)
  File "/home/quang/Desktop/Python/blog-django/venv/lib/python3.8/site-packages/rest_framework/serializers.py", line 768, in data
    ret = super().data
  File "/home/quang/Desktop/Python/blog-django/venv/lib/python3.8/site-packages/rest_framework/serializers.py", line 253, in data
    self._data = self.to_representation(self.instance)
  File "/home/quang/Desktop/Python/blog-django/venv/lib/python3.8/site-packages/rest_framework/serializers.py", line 686, in to_representation
    return [
  File "/home/quang/Desktop/Python/blog-django/venv/lib/python3.8/site-packages/rest_framework/serializers.py", line 687, in <listcomp>
    self.child.to_representation(item) for item in iterable
  File "/home/quang/Desktop/Python/blog-django/venv/lib/python3.8/site-packages/rest_framework/serializers.py", line 507, in to_representation
    for field in fields:
  File "/home/quang/Desktop/Python/blog-django/venv/lib/python3.8/site-packages/rest_framework/serializers.py", line 368, in _readable_fields
    for field in self.fields.values():
  File "/home/quang/Desktop/Python/blog-django/venv/lib/python3.8/site-packages/django/utils/functional.py", line 57, in __get__
    res = instance.__dict__[self.name] = self.func(instance)
  File "/home/quang/Desktop/Python/blog-django/venv/lib/python3.8/site-packages/rest_framework/serializers.py", line 356, in fields
    for key, value in self.get_fields().items():
  File "/home/quang/Desktop/Python/blog-django/venv/lib/python3.8/site-packages/rest_framework/serializers.py", line 1051, in get_fields
    info = model_meta.get_field_info(model)
  File "/home/quang/Desktop/Python/blog-django/venv/lib/python3.8/site-packages/rest_framework/utils/model_meta.py", line 35, in get_field_info
    opts = model._meta.concrete_model._meta
AttributeError: 'str' object has no attribute '_meta'
2022-08-18 01:34:08 ERROR 'str' object has no attribute '_meta'
Traceback (most recent call last):
  File "/home/quang/Desktop/Python/blog-django/venv/lib/python3.8/site-packages/django/core/handlers/base.py", line 197, in _get_response
    response = wrapped_callback(request, *callback_args, **callback_kwargs)
  File "/usr/lib/python3.8/contextlib.py", line 75, in inner
    return func(*args, **kwds)
  File "/home/quang/Desktop/Python/blog-django/venv/lib/python3.8/site-packages/django/views/decorators/csrf.py", line 54, in wrapped_view
    return view_func(*args, **kwargs)
  File "/home/quang/Desktop/Python/blog-django/venv/lib/python3.8/site-packages/rest_framework/viewsets.py", line 125, in view
    return self.dispatch(request, *args, **kwargs)
  File "/home/quang/Desktop/Python/blog-django/venv/lib/python3.8/site-packages/rest_framework/views.py", line 509, in dispatch
    response = self.handle_exception(exc)
  File "/home/quang/Desktop/Python/blog-django/venv/lib/python3.8/site-packages/rest_framework/views.py", line 469, in handle_exception
    self.raise_uncaught_exception(exc)
  File "/home/quang/Desktop/Python/blog-django/venv/lib/python3.8/site-packages/rest_framework/views.py", line 480, in raise_uncaught_exception
    raise exc
  File "/home/quang/Desktop/Python/blog-django/venv/lib/python3.8/site-packages/rest_framework/views.py", line 506, in dispatch
    response = handler(request, *args, **kwargs)
  File "/home/quang/Desktop/Python/blog-django/venv/lib/python3.8/site-packages/rest_framework/mixins.py", line 43, in list
    return self.get_paginated_response(serializer.data)
  File "/home/quang/Desktop/Python/blog-django/venv/lib/python3.8/site-packages/rest_framework/serializers.py", line 768, in data
    ret = super().data
  File "/home/quang/Desktop/Python/blog-django/venv/lib/python3.8/site-packages/rest_framework/serializers.py", line 253, in data
    self._data = self.to_representation(self.instance)
  File "/home/quang/Desktop/Python/blog-django/venv/lib/python3.8/site-packages/rest_framework/serializers.py", line 686, in to_representation
    return [
  File "/home/quang/Desktop/Python/blog-django/venv/lib/python3.8/site-packages/rest_framework/serializers.py", line 687, in <listcomp>
    self.child.to_representation(item) for item in iterable
  File "/home/quang/Desktop/Python/blog-django/venv/lib/python3.8/site-packages/rest_framework/serializers.py", line 507, in to_representation
    for field in fields:
  File "/home/quang/Desktop/Python/blog-django/venv/lib/python3.8/site-packages/rest_framework/serializers.py", line 368, in _readable_fields
    for field in self.fields.values():
  File "/home/quang/Desktop/Python/blog-django/venv/lib/python3.8/site-packages/django/utils/functional.py", line 57, in __get__
    res = instance.__dict__[self.name] = self.func(instance)
  File "/home/quang/Desktop/Python/blog-django/venv/lib/python3.8/site-packages/rest_framework/serializers.py", line 356, in fields
    for key, value in self.get_fields().items():
  File "/home/quang/Desktop/Python/blog-django/venv/lib/python3.8/site-packages/rest_framework/serializers.py", line 1051, in get_fields
    info = model_meta.get_field_info(model)
  File "/home/quang/Desktop/Python/blog-django/venv/lib/python3.8/site-packages/rest_framework/utils/model_meta.py", line 35, in get_field_info
    opts = model._meta.concrete_model._meta
AttributeError: 'str' object has no attribute '_meta'
2022-08-18 01:35:02 ERROR 'str' object has no attribute '_meta'
Traceback (most recent call last):
  File "/home/quang/Desktop/Python/blog-django/venv/lib/python3.8/site-packages/django/core/handlers/base.py", line 197, in _get_response
    response = wrapped_callback(request, *callback_args, **callback_kwargs)
  File "/usr/lib/python3.8/contextlib.py", line 75, in inner
    return func(*args, **kwds)
  File "/home/quang/Desktop/Python/blog-django/venv/lib/python3.8/site-packages/django/views/decorators/csrf.py", line 54, in wrapped_view
    return view_func(*args, **kwargs)
  File "/home/quang/Desktop/Python/blog-django/venv/lib/python3.8/site-packages/rest_framework/viewsets.py", line 125, in view
    return self.dispatch(request, *args, **kwargs)
  File "/home/quang/Desktop/Python/blog-django/venv/lib/python3.8/site-packages/rest_framework/views.py", line 509, in dispatch
    response = self.handle_exception(exc)
  File "/home/quang/Desktop/Python/blog-django/venv/lib/python3.8/site-packages/rest_framework/views.py", line 469, in handle_exception
    self.raise_uncaught_exception(exc)
  File "/home/quang/Desktop/Python/blog-django/venv/lib/python3.8/site-packages/rest_framework/views.py", line 480, in raise_uncaught_exception
    raise exc
  File "/home/quang/Desktop/Python/blog-django/venv/lib/python3.8/site-packages/rest_framework/views.py", line 506, in dispatch
    response = handler(request, *args, **kwargs)
  File "/home/quang/Desktop/Python/blog-django/venv/lib/python3.8/site-packages/rest_framework/mixins.py", line 43, in list
    return self.get_paginated_response(serializer.data)
  File "/home/quang/Desktop/Python/blog-django/venv/lib/python3.8/site-packages/rest_framework/serializers.py", line 768, in data
    ret = super().data
  File "/home/quang/Desktop/Python/blog-django/venv/lib/python3.8/site-packages/rest_framework/serializers.py", line 253, in data
    self._data = self.to_representation(self.instance)
  File "/home/quang/Desktop/Python/blog-django/venv/lib/python3.8/site-packages/rest_framework/serializers.py", line 686, in to_representation
    return [
  File "/home/quang/Desktop/Python/blog-django/venv/lib/python3.8/site-packages/rest_framework/serializers.py", line 687, in <listcomp>
    self.child.to_representation(item) for item in iterable
  File "/home/quang/Desktop/Python/blog-django/venv/lib/python3.8/site-packages/rest_framework/serializers.py", line 507, in to_representation
    for field in fields:
  File "/home/quang/Desktop/Python/blog-django/venv/lib/python3.8/site-packages/rest_framework/serializers.py", line 368, in _readable_fields
    for field in self.fields.values():
  File "/home/quang/Desktop/Python/blog-django/venv/lib/python3.8/site-packages/django/utils/functional.py", line 57, in __get__
    res = instance.__dict__[self.name] = self.func(instance)
  File "/home/quang/Desktop/Python/blog-django/venv/lib/python3.8/site-packages/rest_framework/serializers.py", line 356, in fields
    for key, value in self.get_fields().items():
  File "/home/quang/Desktop/Python/blog-django/venv/lib/python3.8/site-packages/rest_framework/serializers.py", line 1051, in get_fields
    info = model_meta.get_field_info(model)
  File "/home/quang/Desktop/Python/blog-django/venv/lib/python3.8/site-packages/rest_framework/utils/model_meta.py", line 35, in get_field_info
    opts = model._meta.concrete_model._meta
AttributeError: 'str' object has no attribute '_meta'
2022-08-18 01:35:11 ERROR 'str' object has no attribute '_meta'
Traceback (most recent call last):
  File "/home/quang/Desktop/Python/blog-django/venv/lib/python3.8/site-packages/django/core/handlers/base.py", line 197, in _get_response
    response = wrapped_callback(request, *callback_args, **callback_kwargs)
  File "/usr/lib/python3.8/contextlib.py", line 75, in inner
    return func(*args, **kwds)
  File "/home/quang/Desktop/Python/blog-django/venv/lib/python3.8/site-packages/django/views/decorators/csrf.py", line 54, in wrapped_view
    return view_func(*args, **kwargs)
  File "/home/quang/Desktop/Python/blog-django/venv/lib/python3.8/site-packages/rest_framework/viewsets.py", line 125, in view
    return self.dispatch(request, *args, **kwargs)
  File "/home/quang/Desktop/Python/blog-django/venv/lib/python3.8/site-packages/rest_framework/views.py", line 509, in dispatch
    response = self.handle_exception(exc)
  File "/home/quang/Desktop/Python/blog-django/venv/lib/python3.8/site-packages/rest_framework/views.py", line 469, in handle_exception
    self.raise_uncaught_exception(exc)
  File "/home/quang/Desktop/Python/blog-django/venv/lib/python3.8/site-packages/rest_framework/views.py", line 480, in raise_uncaught_exception
    raise exc
  File "/home/quang/Desktop/Python/blog-django/venv/lib/python3.8/site-packages/rest_framework/views.py", line 506, in dispatch
    response = handler(request, *args, **kwargs)
  File "/home/quang/Desktop/Python/blog-django/venv/lib/python3.8/site-packages/rest_framework/mixins.py", line 43, in list
    return self.get_paginated_response(serializer.data)
  File "/home/quang/Desktop/Python/blog-django/venv/lib/python3.8/site-packages/rest_framework/serializers.py", line 768, in data
    ret = super().data
  File "/home/quang/Desktop/Python/blog-django/venv/lib/python3.8/site-packages/rest_framework/serializers.py", line 253, in data
    self._data = self.to_representation(self.instance)
  File "/home/quang/Desktop/Python/blog-django/venv/lib/python3.8/site-packages/rest_framework/serializers.py", line 686, in to_representation
    return [
  File "/home/quang/Desktop/Python/blog-django/venv/lib/python3.8/site-packages/rest_framework/serializers.py", line 687, in <listcomp>
    self.child.to_representation(item) for item in iterable
  File "/home/quang/Desktop/Python/blog-django/venv/lib/python3.8/site-packages/rest_framework/serializers.py", line 507, in to_representation
    for field in fields:
  File "/home/quang/Desktop/Python/blog-django/venv/lib/python3.8/site-packages/rest_framework/serializers.py", line 368, in _readable_fields
    for field in self.fields.values():
  File "/home/quang/Desktop/Python/blog-django/venv/lib/python3.8/site-packages/django/utils/functional.py", line 57, in __get__
    res = instance.__dict__[self.name] = self.func(instance)
  File "/home/quang/Desktop/Python/blog-django/venv/lib/python3.8/site-packages/rest_framework/serializers.py", line 356, in fields
    for key, value in self.get_fields().items():
  File "/home/quang/Desktop/Python/blog-django/venv/lib/python3.8/site-packages/rest_framework/serializers.py", line 1051, in get_fields
    info = model_meta.get_field_info(model)
  File "/home/quang/Desktop/Python/blog-django/venv/lib/python3.8/site-packages/rest_framework/utils/model_meta.py", line 35, in get_field_info
    opts = model._meta.concrete_model._meta
AttributeError: 'str' object has no attribute '_meta'
2022-08-18 01:36:05 ERROR 'str' object has no attribute '_meta'
Traceback (most recent call last):
  File "/home/quang/Desktop/Python/blog-django/venv/lib/python3.8/site-packages/django/core/handlers/base.py", line 197, in _get_response
    response = wrapped_callback(request, *callback_args, **callback_kwargs)
  File "/usr/lib/python3.8/contextlib.py", line 75, in inner
    return func(*args, **kwds)
  File "/home/quang/Desktop/Python/blog-django/venv/lib/python3.8/site-packages/django/views/decorators/csrf.py", line 54, in wrapped_view
    return view_func(*args, **kwargs)
  File "/home/quang/Desktop/Python/blog-django/venv/lib/python3.8/site-packages/rest_framework/viewsets.py", line 125, in view
    return self.dispatch(request, *args, **kwargs)
  File "/home/quang/Desktop/Python/blog-django/venv/lib/python3.8/site-packages/rest_framework/views.py", line 509, in dispatch
    response = self.handle_exception(exc)
  File "/home/quang/Desktop/Python/blog-django/venv/lib/python3.8/site-packages/rest_framework/views.py", line 469, in handle_exception
    self.raise_uncaught_exception(exc)
  File "/home/quang/Desktop/Python/blog-django/venv/lib/python3.8/site-packages/rest_framework/views.py", line 480, in raise_uncaught_exception
    raise exc
  File "/home/quang/Desktop/Python/blog-django/venv/lib/python3.8/site-packages/rest_framework/views.py", line 506, in dispatch
    response = handler(request, *args, **kwargs)
  File "/home/quang/Desktop/Python/blog-django/venv/lib/python3.8/site-packages/rest_framework/mixins.py", line 43, in list
    return self.get_paginated_response(serializer.data)
  File "/home/quang/Desktop/Python/blog-django/venv/lib/python3.8/site-packages/rest_framework/serializers.py", line 768, in data
    ret = super().data
  File "/home/quang/Desktop/Python/blog-django/venv/lib/python3.8/site-packages/rest_framework/serializers.py", line 253, in data
    self._data = self.to_representation(self.instance)
  File "/home/quang/Desktop/Python/blog-django/venv/lib/python3.8/site-packages/rest_framework/serializers.py", line 686, in to_representation
    return [
  File "/home/quang/Desktop/Python/blog-django/venv/lib/python3.8/site-packages/rest_framework/serializers.py", line 687, in <listcomp>
    self.child.to_representation(item) for item in iterable
  File "/home/quang/Desktop/Python/blog-django/venv/lib/python3.8/site-packages/rest_framework/serializers.py", line 507, in to_representation
    for field in fields:
  File "/home/quang/Desktop/Python/blog-django/venv/lib/python3.8/site-packages/rest_framework/serializers.py", line 368, in _readable_fields
    for field in self.fields.values():
  File "/home/quang/Desktop/Python/blog-django/venv/lib/python3.8/site-packages/django/utils/functional.py", line 57, in __get__
    res = instance.__dict__[self.name] = self.func(instance)
  File "/home/quang/Desktop/Python/blog-django/venv/lib/python3.8/site-packages/rest_framework/serializers.py", line 356, in fields
    for key, value in self.get_fields().items():
  File "/home/quang/Desktop/Python/blog-django/venv/lib/python3.8/site-packages/rest_framework/serializers.py", line 1051, in get_fields
    info = model_meta.get_field_info(model)
  File "/home/quang/Desktop/Python/blog-django/venv/lib/python3.8/site-packages/rest_framework/utils/model_meta.py", line 35, in get_field_info
    opts = model._meta.concrete_model._meta
AttributeError: 'str' object has no attribute '_meta'
2022-08-18 01:37:43 ERROR 'str' object has no attribute '_meta'
Traceback (most recent call last):
  File "/home/quang/Desktop/Python/blog-django/venv/lib/python3.8/site-packages/django/core/handlers/base.py", line 197, in _get_response
    response = wrapped_callback(request, *callback_args, **callback_kwargs)
  File "/usr/lib/python3.8/contextlib.py", line 75, in inner
    return func(*args, **kwds)
  File "/home/quang/Desktop/Python/blog-django/venv/lib/python3.8/site-packages/django/views/decorators/csrf.py", line 54, in wrapped_view
    return view_func(*args, **kwargs)
  File "/home/quang/Desktop/Python/blog-django/venv/lib/python3.8/site-packages/rest_framework/viewsets.py", line 125, in view
    return self.dispatch(request, *args, **kwargs)
  File "/home/quang/Desktop/Python/blog-django/venv/lib/python3.8/site-packages/rest_framework/views.py", line 509, in dispatch
    response = self.handle_exception(exc)
  File "/home/quang/Desktop/Python/blog-django/venv/lib/python3.8/site-packages/rest_framework/views.py", line 469, in handle_exception
    self.raise_uncaught_exception(exc)
  File "/home/quang/Desktop/Python/blog-django/venv/lib/python3.8/site-packages/rest_framework/views.py", line 480, in raise_uncaught_exception
    raise exc
  File "/home/quang/Desktop/Python/blog-django/venv/lib/python3.8/site-packages/rest_framework/views.py", line 506, in dispatch
    response = handler(request, *args, **kwargs)
  File "/home/quang/Desktop/Python/blog-django/venv/lib/python3.8/site-packages/rest_framework/mixins.py", line 43, in list
    return self.get_paginated_response(serializer.data)
  File "/home/quang/Desktop/Python/blog-django/venv/lib/python3.8/site-packages/rest_framework/serializers.py", line 768, in data
    ret = super().data
  File "/home/quang/Desktop/Python/blog-django/venv/lib/python3.8/site-packages/rest_framework/serializers.py", line 253, in data
    self._data = self.to_representation(self.instance)
  File "/home/quang/Desktop/Python/blog-django/venv/lib/python3.8/site-packages/rest_framework/serializers.py", line 686, in to_representation
    return [
  File "/home/quang/Desktop/Python/blog-django/venv/lib/python3.8/site-packages/rest_framework/serializers.py", line 687, in <listcomp>
    self.child.to_representation(item) for item in iterable
  File "/home/quang/Desktop/Python/blog-django/venv/lib/python3.8/site-packages/rest_framework/serializers.py", line 507, in to_representation
    for field in fields:
  File "/home/quang/Desktop/Python/blog-django/venv/lib/python3.8/site-packages/rest_framework/serializers.py", line 368, in _readable_fields
    for field in self.fields.values():
  File "/home/quang/Desktop/Python/blog-django/venv/lib/python3.8/site-packages/django/utils/functional.py", line 57, in __get__
    res = instance.__dict__[self.name] = self.func(instance)
  File "/home/quang/Desktop/Python/blog-django/venv/lib/python3.8/site-packages/rest_framework/serializers.py", line 356, in fields
    for key, value in self.get_fields().items():
  File "/home/quang/Desktop/Python/blog-django/venv/lib/python3.8/site-packages/rest_framework/serializers.py", line 1051, in get_fields
    info = model_meta.get_field_info(model)
  File "/home/quang/Desktop/Python/blog-django/venv/lib/python3.8/site-packages/rest_framework/utils/model_meta.py", line 35, in get_field_info
    opts = model._meta.concrete_model._meta
AttributeError: 'str' object has no attribute '_meta'
2022-08-18 01:40:52 ERROR 'str' object has no attribute '_meta'
Traceback (most recent call last):
  File "/home/quang/Desktop/Python/blog-django/venv/lib/python3.8/site-packages/django/core/handlers/base.py", line 197, in _get_response
    response = wrapped_callback(request, *callback_args, **callback_kwargs)
  File "/usr/lib/python3.8/contextlib.py", line 75, in inner
    return func(*args, **kwds)
  File "/home/quang/Desktop/Python/blog-django/venv/lib/python3.8/site-packages/django/views/decorators/csrf.py", line 54, in wrapped_view
    return view_func(*args, **kwargs)
  File "/home/quang/Desktop/Python/blog-django/venv/lib/python3.8/site-packages/rest_framework/viewsets.py", line 125, in view
    return self.dispatch(request, *args, **kwargs)
  File "/home/quang/Desktop/Python/blog-django/venv/lib/python3.8/site-packages/rest_framework/views.py", line 509, in dispatch
    response = self.handle_exception(exc)
  File "/home/quang/Desktop/Python/blog-django/venv/lib/python3.8/site-packages/rest_framework/views.py", line 469, in handle_exception
    self.raise_uncaught_exception(exc)
  File "/home/quang/Desktop/Python/blog-django/venv/lib/python3.8/site-packages/rest_framework/views.py", line 480, in raise_uncaught_exception
    raise exc
  File "/home/quang/Desktop/Python/blog-django/venv/lib/python3.8/site-packages/rest_framework/views.py", line 506, in dispatch
    response = handler(request, *args, **kwargs)
  File "/home/quang/Desktop/Python/blog-django/venv/lib/python3.8/site-packages/rest_framework/mixins.py", line 43, in list
    return self.get_paginated_response(serializer.data)
  File "/home/quang/Desktop/Python/blog-django/venv/lib/python3.8/site-packages/rest_framework/serializers.py", line 768, in data
    ret = super().data
  File "/home/quang/Desktop/Python/blog-django/venv/lib/python3.8/site-packages/rest_framework/serializers.py", line 253, in data
    self._data = self.to_representation(self.instance)
  File "/home/quang/Desktop/Python/blog-django/venv/lib/python3.8/site-packages/rest_framework/serializers.py", line 686, in to_representation
    return [
  File "/home/quang/Desktop/Python/blog-django/venv/lib/python3.8/site-packages/rest_framework/serializers.py", line 687, in <listcomp>
    self.child.to_representation(item) for item in iterable
  File "/home/quang/Desktop/Python/blog-django/venv/lib/python3.8/site-packages/rest_framework/serializers.py", line 507, in to_representation
    for field in fields:
  File "/home/quang/Desktop/Python/blog-django/venv/lib/python3.8/site-packages/rest_framework/serializers.py", line 368, in _readable_fields
    for field in self.fields.values():
  File "/home/quang/Desktop/Python/blog-django/venv/lib/python3.8/site-packages/django/utils/functional.py", line 57, in __get__
    res = instance.__dict__[self.name] = self.func(instance)
  File "/home/quang/Desktop/Python/blog-django/venv/lib/python3.8/site-packages/rest_framework/serializers.py", line 356, in fields
    for key, value in self.get_fields().items():
  File "/home/quang/Desktop/Python/blog-django/venv/lib/python3.8/site-packages/rest_framework/serializers.py", line 1051, in get_fields
    info = model_meta.get_field_info(model)
  File "/home/quang/Desktop/Python/blog-django/venv/lib/python3.8/site-packages/rest_framework/utils/model_meta.py", line 35, in get_field_info
    opts = model._meta.concrete_model._meta
AttributeError: 'str' object has no attribute '_meta'
2022-08-18 01:45:23 ERROR 'str' object has no attribute '_meta'
Traceback (most recent call last):
  File "/home/quang/Desktop/Python/blog-django/venv/lib/python3.8/site-packages/django/core/handlers/base.py", line 197, in _get_response
    response = wrapped_callback(request, *callback_args, **callback_kwargs)
  File "/usr/lib/python3.8/contextlib.py", line 75, in inner
    return func(*args, **kwds)
  File "/home/quang/Desktop/Python/blog-django/venv/lib/python3.8/site-packages/django/views/decorators/csrf.py", line 54, in wrapped_view
    return view_func(*args, **kwargs)
  File "/home/quang/Desktop/Python/blog-django/venv/lib/python3.8/site-packages/rest_framework/viewsets.py", line 125, in view
    return self.dispatch(request, *args, **kwargs)
  File "/home/quang/Desktop/Python/blog-django/venv/lib/python3.8/site-packages/rest_framework/views.py", line 509, in dispatch
    response = self.handle_exception(exc)
  File "/home/quang/Desktop/Python/blog-django/venv/lib/python3.8/site-packages/rest_framework/views.py", line 469, in handle_exception
    self.raise_uncaught_exception(exc)
  File "/home/quang/Desktop/Python/blog-django/venv/lib/python3.8/site-packages/rest_framework/views.py", line 480, in raise_uncaught_exception
    raise exc
  File "/home/quang/Desktop/Python/blog-django/venv/lib/python3.8/site-packages/rest_framework/views.py", line 506, in dispatch
    response = handler(request, *args, **kwargs)
  File "/home/quang/Desktop/Python/blog-django/venv/lib/python3.8/site-packages/rest_framework/mixins.py", line 43, in list
    return self.get_paginated_response(serializer.data)
  File "/home/quang/Desktop/Python/blog-django/venv/lib/python3.8/site-packages/rest_framework/serializers.py", line 768, in data
    ret = super().data
  File "/home/quang/Desktop/Python/blog-django/venv/lib/python3.8/site-packages/rest_framework/serializers.py", line 253, in data
    self._data = self.to_representation(self.instance)
  File "/home/quang/Desktop/Python/blog-django/venv/lib/python3.8/site-packages/rest_framework/serializers.py", line 686, in to_representation
    return [
  File "/home/quang/Desktop/Python/blog-django/venv/lib/python3.8/site-packages/rest_framework/serializers.py", line 687, in <listcomp>
    self.child.to_representation(item) for item in iterable
  File "/home/quang/Desktop/Python/blog-django/venv/lib/python3.8/site-packages/rest_framework/serializers.py", line 507, in to_representation
    for field in fields:
  File "/home/quang/Desktop/Python/blog-django/venv/lib/python3.8/site-packages/rest_framework/serializers.py", line 368, in _readable_fields
    for field in self.fields.values():
  File "/home/quang/Desktop/Python/blog-django/venv/lib/python3.8/site-packages/django/utils/functional.py", line 57, in __get__
    res = instance.__dict__[self.name] = self.func(instance)
  File "/home/quang/Desktop/Python/blog-django/venv/lib/python3.8/site-packages/rest_framework/serializers.py", line 356, in fields
    for key, value in self.get_fields().items():
  File "/home/quang/Desktop/Python/blog-django/venv/lib/python3.8/site-packages/rest_framework/serializers.py", line 1051, in get_fields
    info = model_meta.get_field_info(model)
  File "/home/quang/Desktop/Python/blog-django/venv/lib/python3.8/site-packages/rest_framework/utils/model_meta.py", line 35, in get_field_info
    opts = model._meta.concrete_model._meta
AttributeError: 'str' object has no attribute '_meta'
2022-08-18 01:53:21 ERROR 'str' object has no attribute '_meta'
Traceback (most recent call last):
  File "/home/quang/Desktop/Python/blog-django/venv/lib/python3.8/site-packages/django/core/handlers/base.py", line 197, in _get_response
    response = wrapped_callback(request, *callback_args, **callback_kwargs)
  File "/usr/lib/python3.8/contextlib.py", line 75, in inner
    return func(*args, **kwds)
  File "/home/quang/Desktop/Python/blog-django/venv/lib/python3.8/site-packages/django/views/decorators/csrf.py", line 54, in wrapped_view
    return view_func(*args, **kwargs)
  File "/home/quang/Desktop/Python/blog-django/venv/lib/python3.8/site-packages/rest_framework/viewsets.py", line 125, in view
    return self.dispatch(request, *args, **kwargs)
  File "/home/quang/Desktop/Python/blog-django/venv/lib/python3.8/site-packages/rest_framework/views.py", line 509, in dispatch
    response = self.handle_exception(exc)
  File "/home/quang/Desktop/Python/blog-django/venv/lib/python3.8/site-packages/rest_framework/views.py", line 469, in handle_exception
    self.raise_uncaught_exception(exc)
  File "/home/quang/Desktop/Python/blog-django/venv/lib/python3.8/site-packages/rest_framework/views.py", line 480, in raise_uncaught_exception
    raise exc
  File "/home/quang/Desktop/Python/blog-django/venv/lib/python3.8/site-packages/rest_framework/views.py", line 506, in dispatch
    response = handler(request, *args, **kwargs)
  File "/home/quang/Desktop/Python/blog-django/venv/lib/python3.8/site-packages/rest_framework/mixins.py", line 43, in list
    return self.get_paginated_response(serializer.data)
  File "/home/quang/Desktop/Python/blog-django/venv/lib/python3.8/site-packages/rest_framework/serializers.py", line 768, in data
    ret = super().data
  File "/home/quang/Desktop/Python/blog-django/venv/lib/python3.8/site-packages/rest_framework/serializers.py", line 253, in data
    self._data = self.to_representation(self.instance)
  File "/home/quang/Desktop/Python/blog-django/venv/lib/python3.8/site-packages/rest_framework/serializers.py", line 686, in to_representation
    return [
  File "/home/quang/Desktop/Python/blog-django/venv/lib/python3.8/site-packages/rest_framework/serializers.py", line 687, in <listcomp>
    self.child.to_representation(item) for item in iterable
  File "/home/quang/Desktop/Python/blog-django/venv/lib/python3.8/site-packages/rest_framework/serializers.py", line 507, in to_representation
    for field in fields:
  File "/home/quang/Desktop/Python/blog-django/venv/lib/python3.8/site-packages/rest_framework/serializers.py", line 368, in _readable_fields
    for field in self.fields.values():
  File "/home/quang/Desktop/Python/blog-django/venv/lib/python3.8/site-packages/django/utils/functional.py", line 57, in __get__
    res = instance.__dict__[self.name] = self.func(instance)
  File "/home/quang/Desktop/Python/blog-django/venv/lib/python3.8/site-packages/rest_framework/serializers.py", line 356, in fields
    for key, value in self.get_fields().items():
  File "/home/quang/Desktop/Python/blog-django/venv/lib/python3.8/site-packages/rest_framework/serializers.py", line 1051, in get_fields
    info = model_meta.get_field_info(model)
  File "/home/quang/Desktop/Python/blog-django/venv/lib/python3.8/site-packages/rest_framework/utils/model_meta.py", line 35, in get_field_info
    opts = model._meta.concrete_model._meta
AttributeError: 'str' object has no attribute '_meta'
2022-08-18 01:53:37 ERROR 'str' object has no attribute '_meta'
Traceback (most recent call last):
  File "/home/quang/Desktop/Python/blog-django/venv/lib/python3.8/site-packages/django/core/handlers/base.py", line 197, in _get_response
    response = wrapped_callback(request, *callback_args, **callback_kwargs)
  File "/usr/lib/python3.8/contextlib.py", line 75, in inner
    return func(*args, **kwds)
  File "/home/quang/Desktop/Python/blog-django/venv/lib/python3.8/site-packages/django/views/decorators/csrf.py", line 54, in wrapped_view
    return view_func(*args, **kwargs)
  File "/home/quang/Desktop/Python/blog-django/venv/lib/python3.8/site-packages/rest_framework/viewsets.py", line 125, in view
    return self.dispatch(request, *args, **kwargs)
  File "/home/quang/Desktop/Python/blog-django/venv/lib/python3.8/site-packages/rest_framework/views.py", line 509, in dispatch
    response = self.handle_exception(exc)
  File "/home/quang/Desktop/Python/blog-django/venv/lib/python3.8/site-packages/rest_framework/views.py", line 469, in handle_exception
    self.raise_uncaught_exception(exc)
  File "/home/quang/Desktop/Python/blog-django/venv/lib/python3.8/site-packages/rest_framework/views.py", line 480, in raise_uncaught_exception
    raise exc
  File "/home/quang/Desktop/Python/blog-django/venv/lib/python3.8/site-packages/rest_framework/views.py", line 506, in dispatch
    response = handler(request, *args, **kwargs)
  File "/home/quang/Desktop/Python/blog-django/venv/lib/python3.8/site-packages/rest_framework/mixins.py", line 43, in list
    return self.get_paginated_response(serializer.data)
  File "/home/quang/Desktop/Python/blog-django/venv/lib/python3.8/site-packages/rest_framework/serializers.py", line 768, in data
    ret = super().data
  File "/home/quang/Desktop/Python/blog-django/venv/lib/python3.8/site-packages/rest_framework/serializers.py", line 253, in data
    self._data = self.to_representation(self.instance)
  File "/home/quang/Desktop/Python/blog-django/venv/lib/python3.8/site-packages/rest_framework/serializers.py", line 686, in to_representation
    return [
  File "/home/quang/Desktop/Python/blog-django/venv/lib/python3.8/site-packages/rest_framework/serializers.py", line 687, in <listcomp>
    self.child.to_representation(item) for item in iterable
  File "/home/quang/Desktop/Python/blog-django/venv/lib/python3.8/site-packages/rest_framework/serializers.py", line 507, in to_representation
    for field in fields:
  File "/home/quang/Desktop/Python/blog-django/venv/lib/python3.8/site-packages/rest_framework/serializers.py", line 368, in _readable_fields
    for field in self.fields.values():
  File "/home/quang/Desktop/Python/blog-django/venv/lib/python3.8/site-packages/django/utils/functional.py", line 57, in __get__
    res = instance.__dict__[self.name] = self.func(instance)
  File "/home/quang/Desktop/Python/blog-django/venv/lib/python3.8/site-packages/rest_framework/serializers.py", line 356, in fields
    for key, value in self.get_fields().items():
  File "/home/quang/Desktop/Python/blog-django/venv/lib/python3.8/site-packages/rest_framework/serializers.py", line 1051, in get_fields
    info = model_meta.get_field_info(model)
  File "/home/quang/Desktop/Python/blog-django/venv/lib/python3.8/site-packages/rest_framework/utils/model_meta.py", line 35, in get_field_info
    opts = model._meta.concrete_model._meta
AttributeError: 'str' object has no attribute '_meta'
2022-08-18 01:53:38 ERROR 'str' object has no attribute '_meta'
Traceback (most recent call last):
  File "/home/quang/Desktop/Python/blog-django/venv/lib/python3.8/site-packages/django/core/handlers/base.py", line 197, in _get_response
    response = wrapped_callback(request, *callback_args, **callback_kwargs)
  File "/usr/lib/python3.8/contextlib.py", line 75, in inner
    return func(*args, **kwds)
  File "/home/quang/Desktop/Python/blog-django/venv/lib/python3.8/site-packages/django/views/decorators/csrf.py", line 54, in wrapped_view
    return view_func(*args, **kwargs)
  File "/home/quang/Desktop/Python/blog-django/venv/lib/python3.8/site-packages/rest_framework/viewsets.py", line 125, in view
    return self.dispatch(request, *args, **kwargs)
  File "/home/quang/Desktop/Python/blog-django/venv/lib/python3.8/site-packages/rest_framework/views.py", line 509, in dispatch
    response = self.handle_exception(exc)
  File "/home/quang/Desktop/Python/blog-django/venv/lib/python3.8/site-packages/rest_framework/views.py", line 469, in handle_exception
    self.raise_uncaught_exception(exc)
  File "/home/quang/Desktop/Python/blog-django/venv/lib/python3.8/site-packages/rest_framework/views.py", line 480, in raise_uncaught_exception
    raise exc
  File "/home/quang/Desktop/Python/blog-django/venv/lib/python3.8/site-packages/rest_framework/views.py", line 506, in dispatch
    response = handler(request, *args, **kwargs)
  File "/home/quang/Desktop/Python/blog-django/venv/lib/python3.8/site-packages/rest_framework/mixins.py", line 43, in list
    return self.get_paginated_response(serializer.data)
  File "/home/quang/Desktop/Python/blog-django/venv/lib/python3.8/site-packages/rest_framework/serializers.py", line 768, in data
    ret = super().data
  File "/home/quang/Desktop/Python/blog-django/venv/lib/python3.8/site-packages/rest_framework/serializers.py", line 253, in data
    self._data = self.to_representation(self.instance)
  File "/home/quang/Desktop/Python/blog-django/venv/lib/python3.8/site-packages/rest_framework/serializers.py", line 686, in to_representation
    return [
  File "/home/quang/Desktop/Python/blog-django/venv/lib/python3.8/site-packages/rest_framework/serializers.py", line 687, in <listcomp>
    self.child.to_representation(item) for item in iterable
  File "/home/quang/Desktop/Python/blog-django/venv/lib/python3.8/site-packages/rest_framework/serializers.py", line 507, in to_representation
    for field in fields:
  File "/home/quang/Desktop/Python/blog-django/venv/lib/python3.8/site-packages/rest_framework/serializers.py", line 368, in _readable_fields
    for field in self.fields.values():
  File "/home/quang/Desktop/Python/blog-django/venv/lib/python3.8/site-packages/django/utils/functional.py", line 57, in __get__
    res = instance.__dict__[self.name] = self.func(instance)
  File "/home/quang/Desktop/Python/blog-django/venv/lib/python3.8/site-packages/rest_framework/serializers.py", line 356, in fields
    for key, value in self.get_fields().items():
  File "/home/quang/Desktop/Python/blog-django/venv/lib/python3.8/site-packages/rest_framework/serializers.py", line 1051, in get_fields
    info = model_meta.get_field_info(model)
  File "/home/quang/Desktop/Python/blog-django/venv/lib/python3.8/site-packages/rest_framework/utils/model_meta.py", line 35, in get_field_info
    opts = model._meta.concrete_model._meta
AttributeError: 'str' object has no attribute '_meta'
2022-08-18 01:54:10 ERROR 'str' object has no attribute '_meta'
Traceback (most recent call last):
  File "/home/quang/Desktop/Python/blog-django/venv/lib/python3.8/site-packages/django/core/handlers/base.py", line 197, in _get_response
    response = wrapped_callback(request, *callback_args, **callback_kwargs)
  File "/usr/lib/python3.8/contextlib.py", line 75, in inner
    return func(*args, **kwds)
  File "/home/quang/Desktop/Python/blog-django/venv/lib/python3.8/site-packages/django/views/decorators/csrf.py", line 54, in wrapped_view
    return view_func(*args, **kwargs)
  File "/home/quang/Desktop/Python/blog-django/venv/lib/python3.8/site-packages/rest_framework/viewsets.py", line 125, in view
    return self.dispatch(request, *args, **kwargs)
  File "/home/quang/Desktop/Python/blog-django/venv/lib/python3.8/site-packages/rest_framework/views.py", line 509, in dispatch
    response = self.handle_exception(exc)
  File "/home/quang/Desktop/Python/blog-django/venv/lib/python3.8/site-packages/rest_framework/views.py", line 469, in handle_exception
    self.raise_uncaught_exception(exc)
  File "/home/quang/Desktop/Python/blog-django/venv/lib/python3.8/site-packages/rest_framework/views.py", line 480, in raise_uncaught_exception
    raise exc
  File "/home/quang/Desktop/Python/blog-django/venv/lib/python3.8/site-packages/rest_framework/views.py", line 506, in dispatch
    response = handler(request, *args, **kwargs)
  File "/home/quang/Desktop/Python/blog-django/venv/lib/python3.8/site-packages/rest_framework/mixins.py", line 43, in list
    return self.get_paginated_response(serializer.data)
  File "/home/quang/Desktop/Python/blog-django/venv/lib/python3.8/site-packages/rest_framework/serializers.py", line 768, in data
    ret = super().data
  File "/home/quang/Desktop/Python/blog-django/venv/lib/python3.8/site-packages/rest_framework/serializers.py", line 253, in data
    self._data = self.to_representation(self.instance)
  File "/home/quang/Desktop/Python/blog-django/venv/lib/python3.8/site-packages/rest_framework/serializers.py", line 686, in to_representation
    return [
  File "/home/quang/Desktop/Python/blog-django/venv/lib/python3.8/site-packages/rest_framework/serializers.py", line 687, in <listcomp>
    self.child.to_representation(item) for item in iterable
  File "/home/quang/Desktop/Python/blog-django/venv/lib/python3.8/site-packages/rest_framework/serializers.py", line 507, in to_representation
    for field in fields:
  File "/home/quang/Desktop/Python/blog-django/venv/lib/python3.8/site-packages/rest_framework/serializers.py", line 368, in _readable_fields
    for field in self.fields.values():
  File "/home/quang/Desktop/Python/blog-django/venv/lib/python3.8/site-packages/django/utils/functional.py", line 57, in __get__
    res = instance.__dict__[self.name] = self.func(instance)
  File "/home/quang/Desktop/Python/blog-django/venv/lib/python3.8/site-packages/rest_framework/serializers.py", line 356, in fields
    for key, value in self.get_fields().items():
  File "/home/quang/Desktop/Python/blog-django/venv/lib/python3.8/site-packages/rest_framework/serializers.py", line 1051, in get_fields
    info = model_meta.get_field_info(model)
  File "/home/quang/Desktop/Python/blog-django/venv/lib/python3.8/site-packages/rest_framework/utils/model_meta.py", line 35, in get_field_info
    opts = model._meta.concrete_model._meta
AttributeError: 'str' object has no attribute '_meta'
2022-08-18 01:54:26 ERROR 'str' object has no attribute '_meta'
Traceback (most recent call last):
  File "/home/quang/Desktop/Python/blog-django/venv/lib/python3.8/site-packages/django/core/handlers/base.py", line 197, in _get_response
    response = wrapped_callback(request, *callback_args, **callback_kwargs)
  File "/usr/lib/python3.8/contextlib.py", line 75, in inner
    return func(*args, **kwds)
  File "/home/quang/Desktop/Python/blog-django/venv/lib/python3.8/site-packages/django/views/decorators/csrf.py", line 54, in wrapped_view
    return view_func(*args, **kwargs)
  File "/home/quang/Desktop/Python/blog-django/venv/lib/python3.8/site-packages/rest_framework/viewsets.py", line 125, in view
    return self.dispatch(request, *args, **kwargs)
  File "/home/quang/Desktop/Python/blog-django/venv/lib/python3.8/site-packages/rest_framework/views.py", line 509, in dispatch
    response = self.handle_exception(exc)
  File "/home/quang/Desktop/Python/blog-django/venv/lib/python3.8/site-packages/rest_framework/views.py", line 469, in handle_exception
    self.raise_uncaught_exception(exc)
  File "/home/quang/Desktop/Python/blog-django/venv/lib/python3.8/site-packages/rest_framework/views.py", line 480, in raise_uncaught_exception
    raise exc
  File "/home/quang/Desktop/Python/blog-django/venv/lib/python3.8/site-packages/rest_framework/views.py", line 506, in dispatch
    response = handler(request, *args, **kwargs)
  File "/home/quang/Desktop/Python/blog-django/venv/lib/python3.8/site-packages/rest_framework/mixins.py", line 43, in list
    return self.get_paginated_response(serializer.data)
  File "/home/quang/Desktop/Python/blog-django/venv/lib/python3.8/site-packages/rest_framework/serializers.py", line 768, in data
    ret = super().data
  File "/home/quang/Desktop/Python/blog-django/venv/lib/python3.8/site-packages/rest_framework/serializers.py", line 253, in data
    self._data = self.to_representation(self.instance)
  File "/home/quang/Desktop/Python/blog-django/venv/lib/python3.8/site-packages/rest_framework/serializers.py", line 686, in to_representation
    return [
  File "/home/quang/Desktop/Python/blog-django/venv/lib/python3.8/site-packages/rest_framework/serializers.py", line 687, in <listcomp>
    self.child.to_representation(item) for item in iterable
  File "/home/quang/Desktop/Python/blog-django/venv/lib/python3.8/site-packages/rest_framework/serializers.py", line 507, in to_representation
    for field in fields:
  File "/home/quang/Desktop/Python/blog-django/venv/lib/python3.8/site-packages/rest_framework/serializers.py", line 368, in _readable_fields
    for field in self.fields.values():
  File "/home/quang/Desktop/Python/blog-django/venv/lib/python3.8/site-packages/django/utils/functional.py", line 57, in __get__
    res = instance.__dict__[self.name] = self.func(instance)
  File "/home/quang/Desktop/Python/blog-django/venv/lib/python3.8/site-packages/rest_framework/serializers.py", line 356, in fields
    for key, value in self.get_fields().items():
  File "/home/quang/Desktop/Python/blog-django/venv/lib/python3.8/site-packages/rest_framework/serializers.py", line 1051, in get_fields
    info = model_meta.get_field_info(model)
  File "/home/quang/Desktop/Python/blog-django/venv/lib/python3.8/site-packages/rest_framework/utils/model_meta.py", line 35, in get_field_info
    opts = model._meta.concrete_model._meta
AttributeError: 'str' object has no attribute '_meta'
2022-08-18 01:55:05 ERROR 'str' object has no attribute '_meta'
Traceback (most recent call last):
  File "/home/quang/Desktop/Python/blog-django/venv/lib/python3.8/site-packages/django/core/handlers/base.py", line 197, in _get_response
    response = wrapped_callback(request, *callback_args, **callback_kwargs)
  File "/usr/lib/python3.8/contextlib.py", line 75, in inner
    return func(*args, **kwds)
  File "/home/quang/Desktop/Python/blog-django/venv/lib/python3.8/site-packages/django/views/decorators/csrf.py", line 54, in wrapped_view
    return view_func(*args, **kwargs)
  File "/home/quang/Desktop/Python/blog-django/venv/lib/python3.8/site-packages/rest_framework/viewsets.py", line 125, in view
    return self.dispatch(request, *args, **kwargs)
  File "/home/quang/Desktop/Python/blog-django/venv/lib/python3.8/site-packages/rest_framework/views.py", line 509, in dispatch
    response = self.handle_exception(exc)
  File "/home/quang/Desktop/Python/blog-django/venv/lib/python3.8/site-packages/rest_framework/views.py", line 469, in handle_exception
    self.raise_uncaught_exception(exc)
  File "/home/quang/Desktop/Python/blog-django/venv/lib/python3.8/site-packages/rest_framework/views.py", line 480, in raise_uncaught_exception
    raise exc
  File "/home/quang/Desktop/Python/blog-django/venv/lib/python3.8/site-packages/rest_framework/views.py", line 506, in dispatch
    response = handler(request, *args, **kwargs)
  File "/home/quang/Desktop/Python/blog-django/venv/lib/python3.8/site-packages/rest_framework/mixins.py", line 43, in list
    return self.get_paginated_response(serializer.data)
  File "/home/quang/Desktop/Python/blog-django/venv/lib/python3.8/site-packages/rest_framework/serializers.py", line 768, in data
    ret = super().data
  File "/home/quang/Desktop/Python/blog-django/venv/lib/python3.8/site-packages/rest_framework/serializers.py", line 253, in data
    self._data = self.to_representation(self.instance)
  File "/home/quang/Desktop/Python/blog-django/venv/lib/python3.8/site-packages/rest_framework/serializers.py", line 686, in to_representation
    return [
  File "/home/quang/Desktop/Python/blog-django/venv/lib/python3.8/site-packages/rest_framework/serializers.py", line 687, in <listcomp>
    self.child.to_representation(item) for item in iterable
  File "/home/quang/Desktop/Python/blog-django/venv/lib/python3.8/site-packages/rest_framework/serializers.py", line 507, in to_representation
    for field in fields:
  File "/home/quang/Desktop/Python/blog-django/venv/lib/python3.8/site-packages/rest_framework/serializers.py", line 368, in _readable_fields
    for field in self.fields.values():
  File "/home/quang/Desktop/Python/blog-django/venv/lib/python3.8/site-packages/django/utils/functional.py", line 57, in __get__
    res = instance.__dict__[self.name] = self.func(instance)
  File "/home/quang/Desktop/Python/blog-django/venv/lib/python3.8/site-packages/rest_framework/serializers.py", line 356, in fields
    for key, value in self.get_fields().items():
  File "/home/quang/Desktop/Python/blog-django/venv/lib/python3.8/site-packages/rest_framework/serializers.py", line 1051, in get_fields
    info = model_meta.get_field_info(model)
  File "/home/quang/Desktop/Python/blog-django/venv/lib/python3.8/site-packages/rest_framework/utils/model_meta.py", line 35, in get_field_info
    opts = model._meta.concrete_model._meta
AttributeError: 'str' object has no attribute '_meta'
2022-08-18 01:55:19 ERROR 'str' object has no attribute '_meta'
Traceback (most recent call last):
  File "/home/quang/Desktop/Python/blog-django/venv/lib/python3.8/site-packages/django/core/handlers/base.py", line 197, in _get_response
    response = wrapped_callback(request, *callback_args, **callback_kwargs)
  File "/usr/lib/python3.8/contextlib.py", line 75, in inner
    return func(*args, **kwds)
  File "/home/quang/Desktop/Python/blog-django/venv/lib/python3.8/site-packages/django/views/decorators/csrf.py", line 54, in wrapped_view
    return view_func(*args, **kwargs)
  File "/home/quang/Desktop/Python/blog-django/venv/lib/python3.8/site-packages/rest_framework/viewsets.py", line 125, in view
    return self.dispatch(request, *args, **kwargs)
  File "/home/quang/Desktop/Python/blog-django/venv/lib/python3.8/site-packages/rest_framework/views.py", line 509, in dispatch
    response = self.handle_exception(exc)
  File "/home/quang/Desktop/Python/blog-django/venv/lib/python3.8/site-packages/rest_framework/views.py", line 469, in handle_exception
    self.raise_uncaught_exception(exc)
  File "/home/quang/Desktop/Python/blog-django/venv/lib/python3.8/site-packages/rest_framework/views.py", line 480, in raise_uncaught_exception
    raise exc
  File "/home/quang/Desktop/Python/blog-django/venv/lib/python3.8/site-packages/rest_framework/views.py", line 506, in dispatch
    response = handler(request, *args, **kwargs)
  File "/home/quang/Desktop/Python/blog-django/venv/lib/python3.8/site-packages/rest_framework/mixins.py", line 43, in list
    return self.get_paginated_response(serializer.data)
  File "/home/quang/Desktop/Python/blog-django/venv/lib/python3.8/site-packages/rest_framework/serializers.py", line 768, in data
    ret = super().data
  File "/home/quang/Desktop/Python/blog-django/venv/lib/python3.8/site-packages/rest_framework/serializers.py", line 253, in data
    self._data = self.to_representation(self.instance)
  File "/home/quang/Desktop/Python/blog-django/venv/lib/python3.8/site-packages/rest_framework/serializers.py", line 686, in to_representation
    return [
  File "/home/quang/Desktop/Python/blog-django/venv/lib/python3.8/site-packages/rest_framework/serializers.py", line 687, in <listcomp>
    self.child.to_representation(item) for item in iterable
  File "/home/quang/Desktop/Python/blog-django/venv/lib/python3.8/site-packages/rest_framework/serializers.py", line 507, in to_representation
    for field in fields:
  File "/home/quang/Desktop/Python/blog-django/venv/lib/python3.8/site-packages/rest_framework/serializers.py", line 368, in _readable_fields
    for field in self.fields.values():
  File "/home/quang/Desktop/Python/blog-django/venv/lib/python3.8/site-packages/django/utils/functional.py", line 57, in __get__
    res = instance.__dict__[self.name] = self.func(instance)
  File "/home/quang/Desktop/Python/blog-django/venv/lib/python3.8/site-packages/rest_framework/serializers.py", line 356, in fields
    for key, value in self.get_fields().items():
  File "/home/quang/Desktop/Python/blog-django/venv/lib/python3.8/site-packages/rest_framework/serializers.py", line 1051, in get_fields
    info = model_meta.get_field_info(model)
  File "/home/quang/Desktop/Python/blog-django/venv/lib/python3.8/site-packages/rest_framework/utils/model_meta.py", line 35, in get_field_info
    opts = model._meta.concrete_model._meta
AttributeError: 'str' object has no attribute '_meta'
2022-08-18 02:01:57 ERROR 'str' object has no attribute '_meta'
Traceback (most recent call last):
  File "/home/quang/Desktop/Python/blog-django/venv/lib/python3.8/site-packages/django/core/handlers/base.py", line 197, in _get_response
    response = wrapped_callback(request, *callback_args, **callback_kwargs)
  File "/usr/lib/python3.8/contextlib.py", line 75, in inner
    return func(*args, **kwds)
  File "/home/quang/Desktop/Python/blog-django/venv/lib/python3.8/site-packages/django/views/decorators/csrf.py", line 54, in wrapped_view
    return view_func(*args, **kwargs)
  File "/home/quang/Desktop/Python/blog-django/venv/lib/python3.8/site-packages/rest_framework/viewsets.py", line 125, in view
    return self.dispatch(request, *args, **kwargs)
  File "/home/quang/Desktop/Python/blog-django/venv/lib/python3.8/site-packages/rest_framework/views.py", line 509, in dispatch
    response = self.handle_exception(exc)
  File "/home/quang/Desktop/Python/blog-django/venv/lib/python3.8/site-packages/rest_framework/views.py", line 469, in handle_exception
    self.raise_uncaught_exception(exc)
  File "/home/quang/Desktop/Python/blog-django/venv/lib/python3.8/site-packages/rest_framework/views.py", line 480, in raise_uncaught_exception
    raise exc
  File "/home/quang/Desktop/Python/blog-django/venv/lib/python3.8/site-packages/rest_framework/views.py", line 506, in dispatch
    response = handler(request, *args, **kwargs)
  File "/home/quang/Desktop/Python/blog-django/venv/lib/python3.8/site-packages/rest_framework/mixins.py", line 43, in list
    return self.get_paginated_response(serializer.data)
  File "/home/quang/Desktop/Python/blog-django/venv/lib/python3.8/site-packages/rest_framework/serializers.py", line 768, in data
    ret = super().data
  File "/home/quang/Desktop/Python/blog-django/venv/lib/python3.8/site-packages/rest_framework/serializers.py", line 253, in data
    self._data = self.to_representation(self.instance)
  File "/home/quang/Desktop/Python/blog-django/venv/lib/python3.8/site-packages/rest_framework/serializers.py", line 686, in to_representation
    return [
  File "/home/quang/Desktop/Python/blog-django/venv/lib/python3.8/site-packages/rest_framework/serializers.py", line 687, in <listcomp>
    self.child.to_representation(item) for item in iterable
  File "/home/quang/Desktop/Python/blog-django/venv/lib/python3.8/site-packages/rest_framework/serializers.py", line 507, in to_representation
    for field in fields:
  File "/home/quang/Desktop/Python/blog-django/venv/lib/python3.8/site-packages/rest_framework/serializers.py", line 368, in _readable_fields
    for field in self.fields.values():
  File "/home/quang/Desktop/Python/blog-django/venv/lib/python3.8/site-packages/django/utils/functional.py", line 57, in __get__
    res = instance.__dict__[self.name] = self.func(instance)
  File "/home/quang/Desktop/Python/blog-django/venv/lib/python3.8/site-packages/rest_framework/serializers.py", line 356, in fields
    for key, value in self.get_fields().items():
  File "/home/quang/Desktop/Python/blog-django/venv/lib/python3.8/site-packages/rest_framework/serializers.py", line 1051, in get_fields
    info = model_meta.get_field_info(model)
  File "/home/quang/Desktop/Python/blog-django/venv/lib/python3.8/site-packages/rest_framework/utils/model_meta.py", line 35, in get_field_info
    opts = model._meta.concrete_model._meta
AttributeError: 'str' object has no attribute '_meta'
2022-08-18 02:03:19 ERROR 'str' object has no attribute '_meta'
Traceback (most recent call last):
  File "/home/quang/Desktop/Python/blog-django/venv/lib/python3.8/site-packages/django/core/handlers/base.py", line 197, in _get_response
    response = wrapped_callback(request, *callback_args, **callback_kwargs)
  File "/usr/lib/python3.8/contextlib.py", line 75, in inner
    return func(*args, **kwds)
  File "/home/quang/Desktop/Python/blog-django/venv/lib/python3.8/site-packages/django/views/decorators/csrf.py", line 54, in wrapped_view
    return view_func(*args, **kwargs)
  File "/home/quang/Desktop/Python/blog-django/venv/lib/python3.8/site-packages/rest_framework/viewsets.py", line 125, in view
    return self.dispatch(request, *args, **kwargs)
  File "/home/quang/Desktop/Python/blog-django/venv/lib/python3.8/site-packages/rest_framework/views.py", line 509, in dispatch
    response = self.handle_exception(exc)
  File "/home/quang/Desktop/Python/blog-django/venv/lib/python3.8/site-packages/rest_framework/views.py", line 469, in handle_exception
    self.raise_uncaught_exception(exc)
  File "/home/quang/Desktop/Python/blog-django/venv/lib/python3.8/site-packages/rest_framework/views.py", line 480, in raise_uncaught_exception
    raise exc
  File "/home/quang/Desktop/Python/blog-django/venv/lib/python3.8/site-packages/rest_framework/views.py", line 506, in dispatch
    response = handler(request, *args, **kwargs)
  File "/home/quang/Desktop/Python/blog-django/venv/lib/python3.8/site-packages/rest_framework/mixins.py", line 43, in list
    return self.get_paginated_response(serializer.data)
  File "/home/quang/Desktop/Python/blog-django/venv/lib/python3.8/site-packages/rest_framework/serializers.py", line 768, in data
    ret = super().data
  File "/home/quang/Desktop/Python/blog-django/venv/lib/python3.8/site-packages/rest_framework/serializers.py", line 253, in data
    self._data = self.to_representation(self.instance)
  File "/home/quang/Desktop/Python/blog-django/venv/lib/python3.8/site-packages/rest_framework/serializers.py", line 686, in to_representation
    return [
  File "/home/quang/Desktop/Python/blog-django/venv/lib/python3.8/site-packages/rest_framework/serializers.py", line 687, in <listcomp>
    self.child.to_representation(item) for item in iterable
  File "/home/quang/Desktop/Python/blog-django/venv/lib/python3.8/site-packages/rest_framework/serializers.py", line 507, in to_representation
    for field in fields:
  File "/home/quang/Desktop/Python/blog-django/venv/lib/python3.8/site-packages/rest_framework/serializers.py", line 368, in _readable_fields
    for field in self.fields.values():
  File "/home/quang/Desktop/Python/blog-django/venv/lib/python3.8/site-packages/django/utils/functional.py", line 57, in __get__
    res = instance.__dict__[self.name] = self.func(instance)
  File "/home/quang/Desktop/Python/blog-django/venv/lib/python3.8/site-packages/rest_framework/serializers.py", line 356, in fields
    for key, value in self.get_fields().items():
  File "/home/quang/Desktop/Python/blog-django/venv/lib/python3.8/site-packages/rest_framework/serializers.py", line 1051, in get_fields
    info = model_meta.get_field_info(model)
  File "/home/quang/Desktop/Python/blog-django/venv/lib/python3.8/site-packages/rest_framework/utils/model_meta.py", line 35, in get_field_info
    opts = model._meta.concrete_model._meta
AttributeError: 'str' object has no attribute '_meta'
2022-08-18 02:07:25 ERROR local variable 'message' referenced before assignment
Traceback (most recent call last):
  File "/home/quang/Desktop/Python/blog-django/venv/lib/python3.8/site-packages/django/shortcuts.py", line 85, in get_object_or_404
    return queryset.get(*args, **kwargs)
  File "/home/quang/Desktop/Python/blog-django/venv/lib/python3.8/site-packages/django/db/models/query.py", line 650, in get
    raise self.model.DoesNotExist(
apps.authen.models.User.DoesNotExist: User matching query does not exist.

During handling of the above exception, another exception occurred:

Traceback (most recent call last):
  File "/home/quang/Desktop/Python/blog-django/venv/lib/python3.8/site-packages/rest_framework/views.py", line 506, in dispatch
    response = handler(request, *args, **kwargs)
  File "/home/quang/Desktop/Python/blog-django/venv/lib/python3.8/site-packages/rest_framework/mixins.py", line 54, in retrieve
    instance = self.get_object()
  File "/home/quang/Desktop/Python/blog-django/venv/lib/python3.8/site-packages/rest_framework/generics.py", line 96, in get_object
    obj = get_object_or_404(queryset, **filter_kwargs)
  File "/home/quang/Desktop/Python/blog-django/venv/lib/python3.8/site-packages/rest_framework/generics.py", line 19, in get_object_or_404
    return _get_object_or_404(queryset, *filter_args, **filter_kwargs)
  File "/home/quang/Desktop/Python/blog-django/venv/lib/python3.8/site-packages/django/shortcuts.py", line 87, in get_object_or_404
    raise Http404(
django.http.response.Http404: No User matches the given query.

During handling of the above exception, another exception occurred:

Traceback (most recent call last):
  File "/home/quang/Desktop/Python/blog-django/venv/lib/python3.8/site-packages/django/core/handlers/base.py", line 197, in _get_response
    response = wrapped_callback(request, *callback_args, **callback_kwargs)
  File "/usr/lib/python3.8/contextlib.py", line 75, in inner
    return func(*args, **kwds)
  File "/home/quang/Desktop/Python/blog-django/venv/lib/python3.8/site-packages/django/views/decorators/csrf.py", line 54, in wrapped_view
    return view_func(*args, **kwargs)
  File "/home/quang/Desktop/Python/blog-django/venv/lib/python3.8/site-packages/rest_framework/viewsets.py", line 125, in view
    return self.dispatch(request, *args, **kwargs)
  File "/home/quang/Desktop/Python/blog-django/venv/lib/python3.8/site-packages/rest_framework/views.py", line 509, in dispatch
    response = self.handle_exception(exc)
  File "/home/quang/Desktop/Python/blog-django/venv/lib/python3.8/site-packages/rest_framework/views.py", line 466, in handle_exception
    response = exception_handler(exc, context)
  File "/home/quang/Desktop/Python/blog-django/libs/rest_framework/exc_handler.py", line 57, in custom_exception_handler
    'message': message,
UnboundLocalError: local variable 'message' referenced before assignment
2022-08-18 02:50:12 ERROR get_queryset() missing 1 required positional argument: 'request'
Traceback (most recent call last):
  File "/home/quang/Desktop/Python/blog-django/venv/lib/python3.8/site-packages/django/core/handlers/base.py", line 197, in _get_response
    response = wrapped_callback(request, *callback_args, **callback_kwargs)
  File "/usr/lib/python3.8/contextlib.py", line 75, in inner
    return func(*args, **kwds)
  File "/home/quang/Desktop/Python/blog-django/venv/lib/python3.8/site-packages/django/views/decorators/csrf.py", line 54, in wrapped_view
    return view_func(*args, **kwargs)
  File "/home/quang/Desktop/Python/blog-django/venv/lib/python3.8/site-packages/rest_framework/viewsets.py", line 125, in view
    return self.dispatch(request, *args, **kwargs)
  File "/home/quang/Desktop/Python/blog-django/venv/lib/python3.8/site-packages/rest_framework/views.py", line 509, in dispatch
    response = self.handle_exception(exc)
  File "/home/quang/Desktop/Python/blog-django/venv/lib/python3.8/site-packages/rest_framework/views.py", line 469, in handle_exception
    self.raise_uncaught_exception(exc)
  File "/home/quang/Desktop/Python/blog-django/venv/lib/python3.8/site-packages/rest_framework/views.py", line 480, in raise_uncaught_exception
    raise exc
  File "/home/quang/Desktop/Python/blog-django/venv/lib/python3.8/site-packages/rest_framework/views.py", line 506, in dispatch
    response = handler(request, *args, **kwargs)
  File "/home/quang/Desktop/Python/blog-django/venv/lib/python3.8/site-packages/rest_framework/mixins.py", line 38, in list
    queryset = self.filter_queryset(self.get_queryset())
TypeError: get_queryset() missing 1 required positional argument: 'request'
2022-08-18 02:50:24 ERROR get_queryset() missing 1 required positional argument: 'request'
Traceback (most recent call last):
  File "/home/quang/Desktop/Python/blog-django/venv/lib/python3.8/site-packages/django/core/handlers/base.py", line 197, in _get_response
    response = wrapped_callback(request, *callback_args, **callback_kwargs)
  File "/usr/lib/python3.8/contextlib.py", line 75, in inner
    return func(*args, **kwds)
  File "/home/quang/Desktop/Python/blog-django/venv/lib/python3.8/site-packages/django/views/decorators/csrf.py", line 54, in wrapped_view
    return view_func(*args, **kwargs)
  File "/home/quang/Desktop/Python/blog-django/venv/lib/python3.8/site-packages/rest_framework/viewsets.py", line 125, in view
    return self.dispatch(request, *args, **kwargs)
  File "/home/quang/Desktop/Python/blog-django/venv/lib/python3.8/site-packages/rest_framework/views.py", line 509, in dispatch
    response = self.handle_exception(exc)
  File "/home/quang/Desktop/Python/blog-django/venv/lib/python3.8/site-packages/rest_framework/views.py", line 469, in handle_exception
    self.raise_uncaught_exception(exc)
  File "/home/quang/Desktop/Python/blog-django/venv/lib/python3.8/site-packages/rest_framework/views.py", line 480, in raise_uncaught_exception
    raise exc
  File "/home/quang/Desktop/Python/blog-django/venv/lib/python3.8/site-packages/rest_framework/views.py", line 506, in dispatch
    response = handler(request, *args, **kwargs)
  File "/home/quang/Desktop/Python/blog-django/venv/lib/python3.8/site-packages/rest_framework/mixins.py", line 38, in list
    queryset = self.filter_queryset(self.get_queryset())
TypeError: get_queryset() missing 1 required positional argument: 'request'
2022-08-18 02:55:29 ERROR unhashable type: 'list'
Traceback (most recent call last):
  File "/home/quang/Desktop/Python/blog-django/venv/lib/python3.8/site-packages/django/core/handlers/base.py", line 197, in _get_response
    response = wrapped_callback(request, *callback_args, **callback_kwargs)
  File "/usr/lib/python3.8/contextlib.py", line 75, in inner
    return func(*args, **kwds)
  File "/home/quang/Desktop/Python/blog-django/venv/lib/python3.8/site-packages/django/views/decorators/csrf.py", line 54, in wrapped_view
    return view_func(*args, **kwargs)
  File "/home/quang/Desktop/Python/blog-django/venv/lib/python3.8/site-packages/rest_framework/viewsets.py", line 125, in view
    return self.dispatch(request, *args, **kwargs)
  File "/home/quang/Desktop/Python/blog-django/venv/lib/python3.8/site-packages/rest_framework/views.py", line 509, in dispatch
    response = self.handle_exception(exc)
  File "/home/quang/Desktop/Python/blog-django/venv/lib/python3.8/site-packages/rest_framework/views.py", line 469, in handle_exception
    self.raise_uncaught_exception(exc)
  File "/home/quang/Desktop/Python/blog-django/venv/lib/python3.8/site-packages/rest_framework/views.py", line 480, in raise_uncaught_exception
    raise exc
  File "/home/quang/Desktop/Python/blog-django/venv/lib/python3.8/site-packages/rest_framework/views.py", line 506, in dispatch
    response = handler(request, *args, **kwargs)
  File "/home/quang/Desktop/Python/blog-django/venv/lib/python3.8/site-packages/rest_framework/mixins.py", line 38, in list
    queryset = self.filter_queryset(self.get_queryset())
  File "/home/quang/Desktop/Python/blog-django/apps/api/views/blog_view.py", line 19, in get_queryset
    name_category = self.request.query_params.get(['name'])
  File "/home/quang/Desktop/Python/blog-django/venv/lib/python3.8/site-packages/django/utils/datastructures.py", line 122, in get
    val = self[key]
  File "/home/quang/Desktop/Python/blog-django/venv/lib/python3.8/site-packages/django/utils/datastructures.py", line 84, in __getitem__
    list_ = super().__getitem__(key)
TypeError: unhashable type: 'list'
2022-08-18 03:00:31 ERROR type object 'Category' has no attribute 'filter'
Traceback (most recent call last):
  File "/home/quang/Desktop/Python/blog-django/venv/lib/python3.8/site-packages/django/core/handlers/base.py", line 197, in _get_response
    response = wrapped_callback(request, *callback_args, **callback_kwargs)
  File "/usr/lib/python3.8/contextlib.py", line 75, in inner
    return func(*args, **kwds)
  File "/home/quang/Desktop/Python/blog-django/venv/lib/python3.8/site-packages/django/views/decorators/csrf.py", line 54, in wrapped_view
    return view_func(*args, **kwargs)
  File "/home/quang/Desktop/Python/blog-django/venv/lib/python3.8/site-packages/rest_framework/viewsets.py", line 125, in view
    return self.dispatch(request, *args, **kwargs)
  File "/home/quang/Desktop/Python/blog-django/venv/lib/python3.8/site-packages/rest_framework/views.py", line 509, in dispatch
    response = self.handle_exception(exc)
  File "/home/quang/Desktop/Python/blog-django/venv/lib/python3.8/site-packages/rest_framework/views.py", line 469, in handle_exception
    self.raise_uncaught_exception(exc)
  File "/home/quang/Desktop/Python/blog-django/venv/lib/python3.8/site-packages/rest_framework/views.py", line 480, in raise_uncaught_exception
    raise exc
  File "/home/quang/Desktop/Python/blog-django/venv/lib/python3.8/site-packages/rest_framework/views.py", line 506, in dispatch
    response = handler(request, *args, **kwargs)
  File "/home/quang/Desktop/Python/blog-django/venv/lib/python3.8/site-packages/rest_framework/mixins.py", line 38, in list
    queryset = self.filter_queryset(self.get_queryset())
  File "/home/quang/Desktop/Python/blog-django/apps/api/views/blog_view.py", line 21, in get_queryset
    category = Category.filter(name__icontains = name_category)
AttributeError: type object 'Category' has no attribute 'filter'
2022-08-18 03:13:02 ERROR You passed a Serializer instance as data, but probably meant to pass serialized `.data` or `.error`. representation.
Traceback (most recent call last):
  File "/home/quang/Desktop/Python/blog-django/venv/lib/python3.8/site-packages/django/core/handlers/base.py", line 197, in _get_response
    response = wrapped_callback(request, *callback_args, **callback_kwargs)
  File "/usr/lib/python3.8/contextlib.py", line 75, in inner
    return func(*args, **kwds)
  File "/home/quang/Desktop/Python/blog-django/venv/lib/python3.8/site-packages/django/views/decorators/csrf.py", line 54, in wrapped_view
    return view_func(*args, **kwargs)
  File "/home/quang/Desktop/Python/blog-django/venv/lib/python3.8/site-packages/rest_framework/viewsets.py", line 125, in view
    return self.dispatch(request, *args, **kwargs)
  File "/home/quang/Desktop/Python/blog-django/venv/lib/python3.8/site-packages/rest_framework/views.py", line 509, in dispatch
    response = self.handle_exception(exc)
  File "/home/quang/Desktop/Python/blog-django/venv/lib/python3.8/site-packages/rest_framework/views.py", line 469, in handle_exception
    self.raise_uncaught_exception(exc)
  File "/home/quang/Desktop/Python/blog-django/venv/lib/python3.8/site-packages/rest_framework/views.py", line 480, in raise_uncaught_exception
    raise exc
  File "/home/quang/Desktop/Python/blog-django/venv/lib/python3.8/site-packages/rest_framework/views.py", line 506, in dispatch
    response = handler(request, *args, **kwargs)
  File "/home/quang/Desktop/Python/blog-django/apps/api/views/blog_view.py", line 37, in retrieve
    return Response(serializer,status=status.HTTP_200_OK)
  File "/home/quang/Desktop/Python/blog-django/venv/lib/python3.8/site-packages/rest_framework/response.py", line 38, in __init__
    raise AssertionError(msg)
AssertionError: You passed a Serializer instance as data, but probably meant to pass serialized `.data` or `.error`. representation.
2022-08-18 03:13:33 ERROR Got AttributeError when attempting to get a value for field `name` on serializer `CategorySerializer`.
The serializer field might be named incorrectly and not match any attribute or key on the `QuerySet` instance.
Original exception text was: 'QuerySet' object has no attribute 'name'.
Traceback (most recent call last):
  File "/home/quang/Desktop/Python/blog-django/venv/lib/python3.8/site-packages/rest_framework/fields.py", line 457, in get_attribute
    return get_attribute(instance, self.source_attrs)
  File "/home/quang/Desktop/Python/blog-django/venv/lib/python3.8/site-packages/rest_framework/fields.py", line 97, in get_attribute
    instance = getattr(instance, attr)
AttributeError: 'QuerySet' object has no attribute 'name'

During handling of the above exception, another exception occurred:

Traceback (most recent call last):
  File "/home/quang/Desktop/Python/blog-django/venv/lib/python3.8/site-packages/django/core/handlers/base.py", line 197, in _get_response
    response = wrapped_callback(request, *callback_args, **callback_kwargs)
  File "/usr/lib/python3.8/contextlib.py", line 75, in inner
    return func(*args, **kwds)
  File "/home/quang/Desktop/Python/blog-django/venv/lib/python3.8/site-packages/django/views/decorators/csrf.py", line 54, in wrapped_view
    return view_func(*args, **kwargs)
  File "/home/quang/Desktop/Python/blog-django/venv/lib/python3.8/site-packages/rest_framework/viewsets.py", line 125, in view
    return self.dispatch(request, *args, **kwargs)
  File "/home/quang/Desktop/Python/blog-django/venv/lib/python3.8/site-packages/rest_framework/views.py", line 509, in dispatch
    response = self.handle_exception(exc)
  File "/home/quang/Desktop/Python/blog-django/venv/lib/python3.8/site-packages/rest_framework/views.py", line 469, in handle_exception
    self.raise_uncaught_exception(exc)
  File "/home/quang/Desktop/Python/blog-django/venv/lib/python3.8/site-packages/rest_framework/views.py", line 480, in raise_uncaught_exception
    raise exc
  File "/home/quang/Desktop/Python/blog-django/venv/lib/python3.8/site-packages/rest_framework/views.py", line 506, in dispatch
    response = handler(request, *args, **kwargs)
  File "/home/quang/Desktop/Python/blog-django/apps/api/views/blog_view.py", line 37, in retrieve
    return Response(serializer.data,status=status.HTTP_200_OK)
  File "/home/quang/Desktop/Python/blog-django/venv/lib/python3.8/site-packages/rest_framework/serializers.py", line 555, in data
    ret = super().data
  File "/home/quang/Desktop/Python/blog-django/venv/lib/python3.8/site-packages/rest_framework/serializers.py", line 253, in data
    self._data = self.to_representation(self.instance)
  File "/home/quang/Desktop/Python/blog-django/venv/lib/python3.8/site-packages/rest_framework/serializers.py", line 509, in to_representation
    attribute = field.get_attribute(instance)
  File "/home/quang/Desktop/Python/blog-django/venv/lib/python3.8/site-packages/rest_framework/fields.py", line 490, in get_attribute
    raise type(exc)(msg)
AttributeError: Got AttributeError when attempting to get a value for field `name` on serializer `CategorySerializer`.
The serializer field might be named incorrectly and not match any attribute or key on the `QuerySet` instance.
Original exception text was: 'QuerySet' object has no attribute 'name'.
2022-08-18 03:13:35 ERROR Got AttributeError when attempting to get a value for field `name` on serializer `CategorySerializer`.
The serializer field might be named incorrectly and not match any attribute or key on the `QuerySet` instance.
Original exception text was: 'QuerySet' object has no attribute 'name'.
Traceback (most recent call last):
  File "/home/quang/Desktop/Python/blog-django/venv/lib/python3.8/site-packages/rest_framework/fields.py", line 457, in get_attribute
    return get_attribute(instance, self.source_attrs)
  File "/home/quang/Desktop/Python/blog-django/venv/lib/python3.8/site-packages/rest_framework/fields.py", line 97, in get_attribute
    instance = getattr(instance, attr)
AttributeError: 'QuerySet' object has no attribute 'name'

During handling of the above exception, another exception occurred:

Traceback (most recent call last):
  File "/home/quang/Desktop/Python/blog-django/venv/lib/python3.8/site-packages/django/core/handlers/base.py", line 197, in _get_response
    response = wrapped_callback(request, *callback_args, **callback_kwargs)
  File "/usr/lib/python3.8/contextlib.py", line 75, in inner
    return func(*args, **kwds)
  File "/home/quang/Desktop/Python/blog-django/venv/lib/python3.8/site-packages/django/views/decorators/csrf.py", line 54, in wrapped_view
    return view_func(*args, **kwargs)
  File "/home/quang/Desktop/Python/blog-django/venv/lib/python3.8/site-packages/rest_framework/viewsets.py", line 125, in view
    return self.dispatch(request, *args, **kwargs)
  File "/home/quang/Desktop/Python/blog-django/venv/lib/python3.8/site-packages/rest_framework/views.py", line 509, in dispatch
    response = self.handle_exception(exc)
  File "/home/quang/Desktop/Python/blog-django/venv/lib/python3.8/site-packages/rest_framework/views.py", line 469, in handle_exception
    self.raise_uncaught_exception(exc)
  File "/home/quang/Desktop/Python/blog-django/venv/lib/python3.8/site-packages/rest_framework/views.py", line 480, in raise_uncaught_exception
    raise exc
  File "/home/quang/Desktop/Python/blog-django/venv/lib/python3.8/site-packages/rest_framework/views.py", line 506, in dispatch
    response = handler(request, *args, **kwargs)
  File "/home/quang/Desktop/Python/blog-django/apps/api/views/blog_view.py", line 37, in retrieve
    return Response(serializer.data,status=status.HTTP_200_OK)
  File "/home/quang/Desktop/Python/blog-django/venv/lib/python3.8/site-packages/rest_framework/serializers.py", line 555, in data
    ret = super().data
  File "/home/quang/Desktop/Python/blog-django/venv/lib/python3.8/site-packages/rest_framework/serializers.py", line 253, in data
    self._data = self.to_representation(self.instance)
  File "/home/quang/Desktop/Python/blog-django/venv/lib/python3.8/site-packages/rest_framework/serializers.py", line 509, in to_representation
    attribute = field.get_attribute(instance)
  File "/home/quang/Desktop/Python/blog-django/venv/lib/python3.8/site-packages/rest_framework/fields.py", line 490, in get_attribute
    raise type(exc)(msg)
AttributeError: Got AttributeError when attempting to get a value for field `name` on serializer `CategorySerializer`.
The serializer field might be named incorrectly and not match any attribute or key on the `QuerySet` instance.
Original exception text was: 'QuerySet' object has no attribute 'name'.
2022-08-18 03:14:13 ERROR Got AttributeError when attempting to get a value for field `name` on serializer `CategorySerializer`.
The serializer field might be named incorrectly and not match any attribute or key on the `QuerySet` instance.
Original exception text was: 'QuerySet' object has no attribute 'name'.
Traceback (most recent call last):
  File "/home/quang/Desktop/Python/blog-django/venv/lib/python3.8/site-packages/rest_framework/fields.py", line 457, in get_attribute
    return get_attribute(instance, self.source_attrs)
  File "/home/quang/Desktop/Python/blog-django/venv/lib/python3.8/site-packages/rest_framework/fields.py", line 97, in get_attribute
    instance = getattr(instance, attr)
AttributeError: 'QuerySet' object has no attribute 'name'

During handling of the above exception, another exception occurred:

Traceback (most recent call last):
  File "/home/quang/Desktop/Python/blog-django/venv/lib/python3.8/site-packages/django/core/handlers/base.py", line 197, in _get_response
    response = wrapped_callback(request, *callback_args, **callback_kwargs)
  File "/usr/lib/python3.8/contextlib.py", line 75, in inner
    return func(*args, **kwds)
  File "/home/quang/Desktop/Python/blog-django/venv/lib/python3.8/site-packages/django/views/decorators/csrf.py", line 54, in wrapped_view
    return view_func(*args, **kwargs)
  File "/home/quang/Desktop/Python/blog-django/venv/lib/python3.8/site-packages/rest_framework/viewsets.py", line 125, in view
    return self.dispatch(request, *args, **kwargs)
  File "/home/quang/Desktop/Python/blog-django/venv/lib/python3.8/site-packages/rest_framework/views.py", line 509, in dispatch
    response = self.handle_exception(exc)
  File "/home/quang/Desktop/Python/blog-django/venv/lib/python3.8/site-packages/rest_framework/views.py", line 469, in handle_exception
    self.raise_uncaught_exception(exc)
  File "/home/quang/Desktop/Python/blog-django/venv/lib/python3.8/site-packages/rest_framework/views.py", line 480, in raise_uncaught_exception
    raise exc
  File "/home/quang/Desktop/Python/blog-django/venv/lib/python3.8/site-packages/rest_framework/views.py", line 506, in dispatch
    response = handler(request, *args, **kwargs)
  File "/home/quang/Desktop/Python/blog-django/apps/api/views/blog_view.py", line 37, in retrieve
    return Response(serializer.data,status=status.HTTP_200_OK)
  File "/home/quang/Desktop/Python/blog-django/venv/lib/python3.8/site-packages/rest_framework/serializers.py", line 555, in data
    ret = super().data
  File "/home/quang/Desktop/Python/blog-django/venv/lib/python3.8/site-packages/rest_framework/serializers.py", line 253, in data
    self._data = self.to_representation(self.instance)
  File "/home/quang/Desktop/Python/blog-django/venv/lib/python3.8/site-packages/rest_framework/serializers.py", line 509, in to_representation
    attribute = field.get_attribute(instance)
  File "/home/quang/Desktop/Python/blog-django/venv/lib/python3.8/site-packages/rest_framework/fields.py", line 490, in get_attribute
    raise type(exc)(msg)
AttributeError: Got AttributeError when attempting to get a value for field `name` on serializer `CategorySerializer`.
The serializer field might be named incorrectly and not match any attribute or key on the `QuerySet` instance.
Original exception text was: 'QuerySet' object has no attribute 'name'.
2022-08-18 03:14:55 ERROR local variable 'message' referenced before assignment
Traceback (most recent call last):
  File "/home/quang/Desktop/Python/blog-django/apps/api/views/blog_view.py", line 33, in retrieve
    category = Category.objects.get(pk=pk)
  File "/home/quang/Desktop/Python/blog-django/venv/lib/python3.8/site-packages/django/db/models/manager.py", line 85, in manager_method
    return getattr(self.get_queryset(), name)(*args, **kwargs)
  File "/home/quang/Desktop/Python/blog-django/venv/lib/python3.8/site-packages/django/db/models/query.py", line 650, in get
    raise self.model.DoesNotExist(
apps.api.models.blog_model.Category.DoesNotExist: Category matching query does not exist.

During handling of the above exception, another exception occurred:

Traceback (most recent call last):
  File "/home/quang/Desktop/Python/blog-django/venv/lib/python3.8/site-packages/rest_framework/views.py", line 506, in dispatch
    response = handler(request, *args, **kwargs)
  File "/home/quang/Desktop/Python/blog-django/apps/api/views/blog_view.py", line 35, in retrieve
    raise Http404
django.http.response.Http404

During handling of the above exception, another exception occurred:

Traceback (most recent call last):
  File "/home/quang/Desktop/Python/blog-django/venv/lib/python3.8/site-packages/django/core/handlers/base.py", line 197, in _get_response
    response = wrapped_callback(request, *callback_args, **callback_kwargs)
  File "/usr/lib/python3.8/contextlib.py", line 75, in inner
    return func(*args, **kwds)
  File "/home/quang/Desktop/Python/blog-django/venv/lib/python3.8/site-packages/django/views/decorators/csrf.py", line 54, in wrapped_view
    return view_func(*args, **kwargs)
  File "/home/quang/Desktop/Python/blog-django/venv/lib/python3.8/site-packages/rest_framework/viewsets.py", line 125, in view
    return self.dispatch(request, *args, **kwargs)
  File "/home/quang/Desktop/Python/blog-django/venv/lib/python3.8/site-packages/rest_framework/views.py", line 509, in dispatch
    response = self.handle_exception(exc)
  File "/home/quang/Desktop/Python/blog-django/venv/lib/python3.8/site-packages/rest_framework/views.py", line 466, in handle_exception
    response = exception_handler(exc, context)
  File "/home/quang/Desktop/Python/blog-django/libs/rest_framework/exc_handler.py", line 57, in custom_exception_handler
    'message': message,
UnboundLocalError: local variable 'message' referenced before assignment
2022-08-18 03:15:31 ERROR abc
Traceback (most recent call last):
  File "/home/quang/Desktop/Python/blog-django/apps/api/views/blog_view.py", line 33, in retrieve
    category = Category.objects.get(pk=pk)
  File "/home/quang/Desktop/Python/blog-django/venv/lib/python3.8/site-packages/django/db/models/manager.py", line 85, in manager_method
    return getattr(self.get_queryset(), name)(*args, **kwargs)
  File "/home/quang/Desktop/Python/blog-django/venv/lib/python3.8/site-packages/django/db/models/query.py", line 650, in get
    raise self.model.DoesNotExist(
apps.api.models.blog_model.Category.DoesNotExist: Category matching query does not exist.

During handling of the above exception, another exception occurred:

Traceback (most recent call last):
  File "/home/quang/Desktop/Python/blog-django/venv/lib/python3.8/site-packages/django/core/handlers/base.py", line 197, in _get_response
    response = wrapped_callback(request, *callback_args, **callback_kwargs)
  File "/usr/lib/python3.8/contextlib.py", line 75, in inner
    return func(*args, **kwds)
  File "/home/quang/Desktop/Python/blog-django/venv/lib/python3.8/site-packages/django/views/decorators/csrf.py", line 54, in wrapped_view
    return view_func(*args, **kwargs)
  File "/home/quang/Desktop/Python/blog-django/venv/lib/python3.8/site-packages/rest_framework/viewsets.py", line 125, in view
    return self.dispatch(request, *args, **kwargs)
  File "/home/quang/Desktop/Python/blog-django/venv/lib/python3.8/site-packages/rest_framework/views.py", line 509, in dispatch
    response = self.handle_exception(exc)
  File "/home/quang/Desktop/Python/blog-django/venv/lib/python3.8/site-packages/rest_framework/views.py", line 469, in handle_exception
    self.raise_uncaught_exception(exc)
  File "/home/quang/Desktop/Python/blog-django/venv/lib/python3.8/site-packages/rest_framework/views.py", line 480, in raise_uncaught_exception
    raise exc
  File "/home/quang/Desktop/Python/blog-django/venv/lib/python3.8/site-packages/rest_framework/views.py", line 506, in dispatch
    response = handler(request, *args, **kwargs)
  File "/home/quang/Desktop/Python/blog-django/apps/api/views/blog_view.py", line 35, in retrieve
    raise Exception('abc')
Exception: abc
2022-08-18 03:15:32 ERROR abc
Traceback (most recent call last):
  File "/home/quang/Desktop/Python/blog-django/apps/api/views/blog_view.py", line 33, in retrieve
    category = Category.objects.get(pk=pk)
  File "/home/quang/Desktop/Python/blog-django/venv/lib/python3.8/site-packages/django/db/models/manager.py", line 85, in manager_method
    return getattr(self.get_queryset(), name)(*args, **kwargs)
  File "/home/quang/Desktop/Python/blog-django/venv/lib/python3.8/site-packages/django/db/models/query.py", line 650, in get
    raise self.model.DoesNotExist(
apps.api.models.blog_model.Category.DoesNotExist: Category matching query does not exist.

During handling of the above exception, another exception occurred:

Traceback (most recent call last):
  File "/home/quang/Desktop/Python/blog-django/venv/lib/python3.8/site-packages/django/core/handlers/base.py", line 197, in _get_response
    response = wrapped_callback(request, *callback_args, **callback_kwargs)
  File "/usr/lib/python3.8/contextlib.py", line 75, in inner
    return func(*args, **kwds)
  File "/home/quang/Desktop/Python/blog-django/venv/lib/python3.8/site-packages/django/views/decorators/csrf.py", line 54, in wrapped_view
    return view_func(*args, **kwargs)
  File "/home/quang/Desktop/Python/blog-django/venv/lib/python3.8/site-packages/rest_framework/viewsets.py", line 125, in view
    return self.dispatch(request, *args, **kwargs)
  File "/home/quang/Desktop/Python/blog-django/venv/lib/python3.8/site-packages/rest_framework/views.py", line 509, in dispatch
    response = self.handle_exception(exc)
  File "/home/quang/Desktop/Python/blog-django/venv/lib/python3.8/site-packages/rest_framework/views.py", line 469, in handle_exception
    self.raise_uncaught_exception(exc)
  File "/home/quang/Desktop/Python/blog-django/venv/lib/python3.8/site-packages/rest_framework/views.py", line 480, in raise_uncaught_exception
    raise exc
  File "/home/quang/Desktop/Python/blog-django/venv/lib/python3.8/site-packages/rest_framework/views.py", line 506, in dispatch
    response = handler(request, *args, **kwargs)
  File "/home/quang/Desktop/Python/blog-django/apps/api/views/blog_view.py", line 35, in retrieve
    raise Exception('abc')
Exception: abc
2022-08-18 03:15:43 ERROR abc
Traceback (most recent call last):
  File "/home/quang/Desktop/Python/blog-django/apps/api/views/blog_view.py", line 33, in retrieve
    category = Category.objects.get(pk=pk)
  File "/home/quang/Desktop/Python/blog-django/venv/lib/python3.8/site-packages/django/db/models/manager.py", line 85, in manager_method
    return getattr(self.get_queryset(), name)(*args, **kwargs)
  File "/home/quang/Desktop/Python/blog-django/venv/lib/python3.8/site-packages/django/db/models/query.py", line 650, in get
    raise self.model.DoesNotExist(
apps.api.models.blog_model.Category.DoesNotExist: Category matching query does not exist.

During handling of the above exception, another exception occurred:

Traceback (most recent call last):
  File "/home/quang/Desktop/Python/blog-django/venv/lib/python3.8/site-packages/django/core/handlers/base.py", line 197, in _get_response
    response = wrapped_callback(request, *callback_args, **callback_kwargs)
  File "/usr/lib/python3.8/contextlib.py", line 75, in inner
    return func(*args, **kwds)
  File "/home/quang/Desktop/Python/blog-django/venv/lib/python3.8/site-packages/django/views/decorators/csrf.py", line 54, in wrapped_view
    return view_func(*args, **kwargs)
  File "/home/quang/Desktop/Python/blog-django/venv/lib/python3.8/site-packages/rest_framework/viewsets.py", line 125, in view
    return self.dispatch(request, *args, **kwargs)
  File "/home/quang/Desktop/Python/blog-django/venv/lib/python3.8/site-packages/rest_framework/views.py", line 509, in dispatch
    response = self.handle_exception(exc)
  File "/home/quang/Desktop/Python/blog-django/venv/lib/python3.8/site-packages/rest_framework/views.py", line 469, in handle_exception
    self.raise_uncaught_exception(exc)
  File "/home/quang/Desktop/Python/blog-django/venv/lib/python3.8/site-packages/rest_framework/views.py", line 480, in raise_uncaught_exception
    raise exc
  File "/home/quang/Desktop/Python/blog-django/venv/lib/python3.8/site-packages/rest_framework/views.py", line 506, in dispatch
    response = handler(request, *args, **kwargs)
  File "/home/quang/Desktop/Python/blog-django/apps/api/views/blog_view.py", line 35, in retrieve
    raise Exception('abc')
Exception: abc
2022-08-18 04:36:14 ERROR 'str' object has no attribute 'get'
Traceback (most recent call last):
  File "/home/quang/Desktop/Python/blog-django/venv/lib/python3.8/site-packages/django/core/handlers/base.py", line 220, in _get_response
    response = response.render()
  File "/home/quang/Desktop/Python/blog-django/venv/lib/python3.8/site-packages/django/template/response.py", line 114, in render
    self.content = self.rendered_content
  File "/home/quang/Desktop/Python/blog-django/venv/lib/python3.8/site-packages/rest_framework/response.py", line 70, in rendered_content
    ret = renderer.render(self.data, accepted_media_type, context)
  File "/home/quang/Desktop/Python/blog-django/libs/rest_framework/renderers.py", line 21, in render
    ret['error'] = data.get('error')
AttributeError: 'str' object has no attribute 'get'
2022-08-18 04:50:38 ERROR custom_exception_handler() missing 1 required positional argument: 'context'
Traceback (most recent call last):
  File "/home/quang/Desktop/Python/blog-django/apps/api/views/blog_view.py", line 35, in retrieve
    category = Category.objects.get(pk=pk)
  File "/home/quang/Desktop/Python/blog-django/venv/lib/python3.8/site-packages/django/db/models/manager.py", line 85, in manager_method
    return getattr(self.get_queryset(), name)(*args, **kwargs)
  File "/home/quang/Desktop/Python/blog-django/venv/lib/python3.8/site-packages/django/db/models/query.py", line 650, in get
    raise self.model.DoesNotExist(
apps.api.models.blog_model.Category.DoesNotExist: Category matching query does not exist.

During handling of the above exception, another exception occurred:

Traceback (most recent call last):
  File "/home/quang/Desktop/Python/blog-django/venv/lib/python3.8/site-packages/django/core/handlers/base.py", line 197, in _get_response
    response = wrapped_callback(request, *callback_args, **callback_kwargs)
  File "/usr/lib/python3.8/contextlib.py", line 75, in inner
    return func(*args, **kwds)
  File "/home/quang/Desktop/Python/blog-django/venv/lib/python3.8/site-packages/django/views/decorators/csrf.py", line 54, in wrapped_view
    return view_func(*args, **kwargs)
  File "/home/quang/Desktop/Python/blog-django/venv/lib/python3.8/site-packages/rest_framework/viewsets.py", line 125, in view
    return self.dispatch(request, *args, **kwargs)
  File "/home/quang/Desktop/Python/blog-django/venv/lib/python3.8/site-packages/rest_framework/views.py", line 509, in dispatch
    response = self.handle_exception(exc)
  File "/home/quang/Desktop/Python/blog-django/venv/lib/python3.8/site-packages/rest_framework/views.py", line 469, in handle_exception
    self.raise_uncaught_exception(exc)
  File "/home/quang/Desktop/Python/blog-django/venv/lib/python3.8/site-packages/rest_framework/views.py", line 480, in raise_uncaught_exception
    raise exc
  File "/home/quang/Desktop/Python/blog-django/venv/lib/python3.8/site-packages/rest_framework/views.py", line 506, in dispatch
    response = handler(request, *args, **kwargs)
  File "/home/quang/Desktop/Python/blog-django/apps/api/views/blog_view.py", line 37, in retrieve
    return Response(custom_exception_handler(Exception(CategoryExeption)))
TypeError: custom_exception_handler() missing 1 required positional argument: 'context'
2022-08-18 09:03:31 ERROR Field 'id' expected a number but got 'aaaa'.
Traceback (most recent call last):
  File "/home/quang/Desktop/Python/blog-django/venv/lib/python3.8/site-packages/django/db/models/fields/__init__.py", line 2018, in get_prep_value
    return int(value)
ValueError: invalid literal for int() with base 10: 'aaaa'

The above exception was the direct cause of the following exception:

Traceback (most recent call last):
  File "/home/quang/Desktop/Python/blog-django/venv/lib/python3.8/site-packages/django/core/handlers/base.py", line 197, in _get_response
    response = wrapped_callback(request, *callback_args, **callback_kwargs)
  File "/usr/lib/python3.8/contextlib.py", line 75, in inner
    return func(*args, **kwds)
  File "/home/quang/Desktop/Python/blog-django/venv/lib/python3.8/site-packages/django/views/decorators/csrf.py", line 54, in wrapped_view
    return view_func(*args, **kwargs)
  File "/home/quang/Desktop/Python/blog-django/venv/lib/python3.8/site-packages/rest_framework/viewsets.py", line 125, in view
    return self.dispatch(request, *args, **kwargs)
  File "/home/quang/Desktop/Python/blog-django/venv/lib/python3.8/site-packages/rest_framework/views.py", line 509, in dispatch
    response = self.handle_exception(exc)
  File "/home/quang/Desktop/Python/blog-django/venv/lib/python3.8/site-packages/rest_framework/views.py", line 469, in handle_exception
    self.raise_uncaught_exception(exc)
  File "/home/quang/Desktop/Python/blog-django/venv/lib/python3.8/site-packages/rest_framework/views.py", line 480, in raise_uncaught_exception
    raise exc
  File "/home/quang/Desktop/Python/blog-django/venv/lib/python3.8/site-packages/rest_framework/views.py", line 506, in dispatch
    response = handler(request, *args, **kwargs)
  File "/home/quang/Desktop/Python/blog-django/apps/api/views/blog_view.py", line 31, in retrieve
    category = Category.objects.get(pk=pk, is_active = True)
  File "/home/quang/Desktop/Python/blog-django/venv/lib/python3.8/site-packages/django/db/models/manager.py", line 85, in manager_method
    return getattr(self.get_queryset(), name)(*args, **kwargs)
  File "/home/quang/Desktop/Python/blog-django/venv/lib/python3.8/site-packages/django/db/models/query.py", line 636, in get
    clone = self._chain() if self.query.combinator else self.filter(*args, **kwargs)
  File "/home/quang/Desktop/Python/blog-django/venv/lib/python3.8/site-packages/django/db/models/query.py", line 1420, in filter
    return self._filter_or_exclude(False, args, kwargs)
  File "/home/quang/Desktop/Python/blog-django/venv/lib/python3.8/site-packages/django/db/models/query.py", line 1438, in _filter_or_exclude
    clone._filter_or_exclude_inplace(negate, args, kwargs)
  File "/home/quang/Desktop/Python/blog-django/venv/lib/python3.8/site-packages/django/db/models/query.py", line 1445, in _filter_or_exclude_inplace
    self._query.add_q(Q(*args, **kwargs))
  File "/home/quang/Desktop/Python/blog-django/venv/lib/python3.8/site-packages/django/db/models/sql/query.py", line 1532, in add_q
    clause, _ = self._add_q(q_object, self.used_aliases)
  File "/home/quang/Desktop/Python/blog-django/venv/lib/python3.8/site-packages/django/db/models/sql/query.py", line 1562, in _add_q
    child_clause, needed_inner = self.build_filter(
  File "/home/quang/Desktop/Python/blog-django/venv/lib/python3.8/site-packages/django/db/models/sql/query.py", line 1478, in build_filter
    condition = self.build_lookup(lookups, col, value)
  File "/home/quang/Desktop/Python/blog-django/venv/lib/python3.8/site-packages/django/db/models/sql/query.py", line 1303, in build_lookup
    lookup = lookup_class(lhs, rhs)
  File "/home/quang/Desktop/Python/blog-django/venv/lib/python3.8/site-packages/django/db/models/lookups.py", line 27, in __init__
    self.rhs = self.get_prep_lookup()
  File "/home/quang/Desktop/Python/blog-django/venv/lib/python3.8/site-packages/django/db/models/lookups.py", line 341, in get_prep_lookup
    return super().get_prep_lookup()
  File "/home/quang/Desktop/Python/blog-django/venv/lib/python3.8/site-packages/django/db/models/lookups.py", line 85, in get_prep_lookup
    return self.lhs.output_field.get_prep_value(self.rhs)
  File "/home/quang/Desktop/Python/blog-django/venv/lib/python3.8/site-packages/django/db/models/fields/__init__.py", line 2020, in get_prep_value
    raise e.__class__(
ValueError: Field 'id' expected a number but got 'aaaa'.
2022-08-18 09:28:21 ERROR 'Request' object has no attribute 'get'
Traceback (most recent call last):
  File "/home/quang/Desktop/Python/blog-django/venv/lib/python3.8/site-packages/rest_framework/request.py", line 416, in __getattr__
    return getattr(self._request, attr)
AttributeError: 'WSGIRequest' object has no attribute 'get'

During handling of the above exception, another exception occurred:

Traceback (most recent call last):
  File "/home/quang/Desktop/Python/blog-django/venv/lib/python3.8/site-packages/django/core/handlers/base.py", line 197, in _get_response
    response = wrapped_callback(request, *callback_args, **callback_kwargs)
  File "/usr/lib/python3.8/contextlib.py", line 75, in inner
    return func(*args, **kwds)
  File "/home/quang/Desktop/Python/blog-django/venv/lib/python3.8/site-packages/django/views/decorators/csrf.py", line 54, in wrapped_view
    return view_func(*args, **kwargs)
  File "/home/quang/Desktop/Python/blog-django/venv/lib/python3.8/site-packages/rest_framework/viewsets.py", line 125, in view
    return self.dispatch(request, *args, **kwargs)
  File "/home/quang/Desktop/Python/blog-django/venv/lib/python3.8/site-packages/rest_framework/views.py", line 509, in dispatch
    response = self.handle_exception(exc)
  File "/home/quang/Desktop/Python/blog-django/venv/lib/python3.8/site-packages/rest_framework/views.py", line 469, in handle_exception
    self.raise_uncaught_exception(exc)
  File "/home/quang/Desktop/Python/blog-django/venv/lib/python3.8/site-packages/rest_framework/views.py", line 480, in raise_uncaught_exception
    raise exc
  File "/home/quang/Desktop/Python/blog-django/venv/lib/python3.8/site-packages/rest_framework/views.py", line 506, in dispatch
    response = handler(request, *args, **kwargs)
  File "/home/quang/Desktop/Python/blog-django/apps/api/views/blog_view.py", line 30, in retrieve
    print(request.get('pk'))
  File "/home/quang/Desktop/Python/blog-django/venv/lib/python3.8/site-packages/rest_framework/request.py", line 418, in __getattr__
    return self.__getattribute__(attr)
AttributeError: 'Request' object has no attribute 'get'
2022-08-18 09:29:24 ERROR Field 'id' expected a number but got 'aaa'.
Traceback (most recent call last):
  File "/home/quang/Desktop/Python/blog-django/venv/lib/python3.8/site-packages/django/db/models/fields/__init__.py", line 2018, in get_prep_value
    return int(value)
ValueError: invalid literal for int() with base 10: 'aaa'

The above exception was the direct cause of the following exception:

Traceback (most recent call last):
  File "/home/quang/Desktop/Python/blog-django/venv/lib/python3.8/site-packages/django/core/handlers/base.py", line 197, in _get_response
    response = wrapped_callback(request, *callback_args, **callback_kwargs)
  File "/usr/lib/python3.8/contextlib.py", line 75, in inner
    return func(*args, **kwds)
  File "/home/quang/Desktop/Python/blog-django/venv/lib/python3.8/site-packages/django/views/decorators/csrf.py", line 54, in wrapped_view
    return view_func(*args, **kwargs)
  File "/home/quang/Desktop/Python/blog-django/venv/lib/python3.8/site-packages/rest_framework/viewsets.py", line 125, in view
    return self.dispatch(request, *args, **kwargs)
  File "/home/quang/Desktop/Python/blog-django/venv/lib/python3.8/site-packages/rest_framework/views.py", line 509, in dispatch
    response = self.handle_exception(exc)
  File "/home/quang/Desktop/Python/blog-django/venv/lib/python3.8/site-packages/rest_framework/views.py", line 469, in handle_exception
    self.raise_uncaught_exception(exc)
  File "/home/quang/Desktop/Python/blog-django/venv/lib/python3.8/site-packages/rest_framework/views.py", line 480, in raise_uncaught_exception
    raise exc
  File "/home/quang/Desktop/Python/blog-django/venv/lib/python3.8/site-packages/rest_framework/views.py", line 506, in dispatch
    response = handler(request, *args, **kwargs)
  File "/home/quang/Desktop/Python/blog-django/apps/api/views/blog_view.py", line 32, in retrieve
    category = Category.objects.get(pk=pk, is_active=True)
  File "/home/quang/Desktop/Python/blog-django/venv/lib/python3.8/site-packages/django/db/models/manager.py", line 85, in manager_method
    return getattr(self.get_queryset(), name)(*args, **kwargs)
  File "/home/quang/Desktop/Python/blog-django/venv/lib/python3.8/site-packages/django/db/models/query.py", line 636, in get
    clone = self._chain() if self.query.combinator else self.filter(*args, **kwargs)
  File "/home/quang/Desktop/Python/blog-django/venv/lib/python3.8/site-packages/django/db/models/query.py", line 1420, in filter
    return self._filter_or_exclude(False, args, kwargs)
  File "/home/quang/Desktop/Python/blog-django/venv/lib/python3.8/site-packages/django/db/models/query.py", line 1438, in _filter_or_exclude
    clone._filter_or_exclude_inplace(negate, args, kwargs)
  File "/home/quang/Desktop/Python/blog-django/venv/lib/python3.8/site-packages/django/db/models/query.py", line 1445, in _filter_or_exclude_inplace
    self._query.add_q(Q(*args, **kwargs))
  File "/home/quang/Desktop/Python/blog-django/venv/lib/python3.8/site-packages/django/db/models/sql/query.py", line 1532, in add_q
    clause, _ = self._add_q(q_object, self.used_aliases)
  File "/home/quang/Desktop/Python/blog-django/venv/lib/python3.8/site-packages/django/db/models/sql/query.py", line 1562, in _add_q
    child_clause, needed_inner = self.build_filter(
  File "/home/quang/Desktop/Python/blog-django/venv/lib/python3.8/site-packages/django/db/models/sql/query.py", line 1478, in build_filter
    condition = self.build_lookup(lookups, col, value)
  File "/home/quang/Desktop/Python/blog-django/venv/lib/python3.8/site-packages/django/db/models/sql/query.py", line 1303, in build_lookup
    lookup = lookup_class(lhs, rhs)
  File "/home/quang/Desktop/Python/blog-django/venv/lib/python3.8/site-packages/django/db/models/lookups.py", line 27, in __init__
    self.rhs = self.get_prep_lookup()
  File "/home/quang/Desktop/Python/blog-django/venv/lib/python3.8/site-packages/django/db/models/lookups.py", line 341, in get_prep_lookup
    return super().get_prep_lookup()
  File "/home/quang/Desktop/Python/blog-django/venv/lib/python3.8/site-packages/django/db/models/lookups.py", line 85, in get_prep_lookup
    return self.lhs.output_field.get_prep_value(self.rhs)
  File "/home/quang/Desktop/Python/blog-django/venv/lib/python3.8/site-packages/django/db/models/fields/__init__.py", line 2020, in get_prep_value
    raise e.__class__(
ValueError: Field 'id' expected a number but got 'aaa'.
2022-08-18 09:30:15 ERROR invalid literal for int() with base 10: 'aaa'
Traceback (most recent call last):
  File "/home/quang/Desktop/Python/blog-django/venv/lib/python3.8/site-packages/django/core/handlers/base.py", line 197, in _get_response
    response = wrapped_callback(request, *callback_args, **callback_kwargs)
  File "/usr/lib/python3.8/contextlib.py", line 75, in inner
    return func(*args, **kwds)
  File "/home/quang/Desktop/Python/blog-django/venv/lib/python3.8/site-packages/django/views/decorators/csrf.py", line 54, in wrapped_view
    return view_func(*args, **kwargs)
  File "/home/quang/Desktop/Python/blog-django/venv/lib/python3.8/site-packages/rest_framework/viewsets.py", line 125, in view
    return self.dispatch(request, *args, **kwargs)
  File "/home/quang/Desktop/Python/blog-django/venv/lib/python3.8/site-packages/rest_framework/views.py", line 509, in dispatch
    response = self.handle_exception(exc)
  File "/home/quang/Desktop/Python/blog-django/venv/lib/python3.8/site-packages/rest_framework/views.py", line 469, in handle_exception
    self.raise_uncaught_exception(exc)
  File "/home/quang/Desktop/Python/blog-django/venv/lib/python3.8/site-packages/rest_framework/views.py", line 480, in raise_uncaught_exception
    raise exc
  File "/home/quang/Desktop/Python/blog-django/venv/lib/python3.8/site-packages/rest_framework/views.py", line 506, in dispatch
    response = handler(request, *args, **kwargs)
  File "/home/quang/Desktop/Python/blog-django/apps/api/views/blog_view.py", line 30, in retrieve
    id_cate = int(pk)
ValueError: invalid literal for int() with base 10: 'aaa'
2022-08-18 09:30:21 ERROR invalid literal for int() with base 10: 'aaa'
Traceback (most recent call last):
  File "/home/quang/Desktop/Python/blog-django/venv/lib/python3.8/site-packages/django/core/handlers/base.py", line 197, in _get_response
    response = wrapped_callback(request, *callback_args, **callback_kwargs)
  File "/usr/lib/python3.8/contextlib.py", line 75, in inner
    return func(*args, **kwds)
  File "/home/quang/Desktop/Python/blog-django/venv/lib/python3.8/site-packages/django/views/decorators/csrf.py", line 54, in wrapped_view
    return view_func(*args, **kwargs)
  File "/home/quang/Desktop/Python/blog-django/venv/lib/python3.8/site-packages/rest_framework/viewsets.py", line 125, in view
    return self.dispatch(request, *args, **kwargs)
  File "/home/quang/Desktop/Python/blog-django/venv/lib/python3.8/site-packages/rest_framework/views.py", line 509, in dispatch
    response = self.handle_exception(exc)
  File "/home/quang/Desktop/Python/blog-django/venv/lib/python3.8/site-packages/rest_framework/views.py", line 469, in handle_exception
    self.raise_uncaught_exception(exc)
  File "/home/quang/Desktop/Python/blog-django/venv/lib/python3.8/site-packages/rest_framework/views.py", line 480, in raise_uncaught_exception
    raise exc
  File "/home/quang/Desktop/Python/blog-django/venv/lib/python3.8/site-packages/rest_framework/views.py", line 506, in dispatch
    response = handler(request, *args, **kwargs)
  File "/home/quang/Desktop/Python/blog-django/apps/api/views/blog_view.py", line 30, in retrieve
    id_cate = int(pk)
ValueError: invalid literal for int() with base 10: 'aaa'
2022-08-18 09:30:44 ERROR invalid literal for int() with base 10: 'aa'
Traceback (most recent call last):
  File "/home/quang/Desktop/Python/blog-django/venv/lib/python3.8/site-packages/django/core/handlers/base.py", line 197, in _get_response
    response = wrapped_callback(request, *callback_args, **callback_kwargs)
  File "/usr/lib/python3.8/contextlib.py", line 75, in inner
    return func(*args, **kwds)
  File "/home/quang/Desktop/Python/blog-django/venv/lib/python3.8/site-packages/django/views/decorators/csrf.py", line 54, in wrapped_view
    return view_func(*args, **kwargs)
  File "/home/quang/Desktop/Python/blog-django/venv/lib/python3.8/site-packages/rest_framework/viewsets.py", line 125, in view
    return self.dispatch(request, *args, **kwargs)
  File "/home/quang/Desktop/Python/blog-django/venv/lib/python3.8/site-packages/rest_framework/views.py", line 509, in dispatch
    response = self.handle_exception(exc)
  File "/home/quang/Desktop/Python/blog-django/venv/lib/python3.8/site-packages/rest_framework/views.py", line 469, in handle_exception
    self.raise_uncaught_exception(exc)
  File "/home/quang/Desktop/Python/blog-django/venv/lib/python3.8/site-packages/rest_framework/views.py", line 480, in raise_uncaught_exception
    raise exc
  File "/home/quang/Desktop/Python/blog-django/venv/lib/python3.8/site-packages/rest_framework/views.py", line 506, in dispatch
    response = handler(request, *args, **kwargs)
  File "/home/quang/Desktop/Python/blog-django/apps/api/views/blog_view.py", line 30, in retrieve
    id_cate = int(pk)
ValueError: invalid literal for int() with base 10: 'aa'
2022-08-19 01:49:14 ERROR not enough values to unpack (expected 2, got 1)
Traceback (most recent call last):
  File "/home/quang/Desktop/Python/blog-django/venv/lib/python3.8/site-packages/django/core/handlers/base.py", line 197, in _get_response
    response = wrapped_callback(request, *callback_args, **callback_kwargs)
  File "/usr/lib/python3.8/contextlib.py", line 75, in inner
    return func(*args, **kwds)
  File "/home/quang/Desktop/Python/blog-django/venv/lib/python3.8/site-packages/django/views/decorators/csrf.py", line 54, in wrapped_view
    return view_func(*args, **kwargs)
  File "/home/quang/Desktop/Python/blog-django/venv/lib/python3.8/site-packages/rest_framework/viewsets.py", line 125, in view
    return self.dispatch(request, *args, **kwargs)
  File "/home/quang/Desktop/Python/blog-django/venv/lib/python3.8/site-packages/rest_framework/views.py", line 509, in dispatch
    response = self.handle_exception(exc)
  File "/home/quang/Desktop/Python/blog-django/venv/lib/python3.8/site-packages/rest_framework/views.py", line 469, in handle_exception
    self.raise_uncaught_exception(exc)
  File "/home/quang/Desktop/Python/blog-django/venv/lib/python3.8/site-packages/rest_framework/views.py", line 480, in raise_uncaught_exception
    raise exc
  File "/home/quang/Desktop/Python/blog-django/venv/lib/python3.8/site-packages/rest_framework/views.py", line 506, in dispatch
    response = handler(request, *args, **kwargs)
  File "/home/quang/Desktop/Python/blog-django/apps/api/views/blog_view.py", line 32, in retrieve
    category = get_object_or_404(queryset,pk)
  File "/home/quang/Desktop/Python/blog-django/venv/lib/python3.8/site-packages/django/shortcuts.py", line 85, in get_object_or_404
    return queryset.get(*args, **kwargs)
  File "/home/quang/Desktop/Python/blog-django/venv/lib/python3.8/site-packages/django/db/models/query.py", line 636, in get
    clone = self._chain() if self.query.combinator else self.filter(*args, **kwargs)
  File "/home/quang/Desktop/Python/blog-django/venv/lib/python3.8/site-packages/django/db/models/query.py", line 1420, in filter
    return self._filter_or_exclude(False, args, kwargs)
  File "/home/quang/Desktop/Python/blog-django/venv/lib/python3.8/site-packages/django/db/models/query.py", line 1438, in _filter_or_exclude
    clone._filter_or_exclude_inplace(negate, args, kwargs)
  File "/home/quang/Desktop/Python/blog-django/venv/lib/python3.8/site-packages/django/db/models/query.py", line 1445, in _filter_or_exclude_inplace
    self._query.add_q(Q(*args, **kwargs))
  File "/home/quang/Desktop/Python/blog-django/venv/lib/python3.8/site-packages/django/db/models/sql/query.py", line 1532, in add_q
    clause, _ = self._add_q(q_object, self.used_aliases)
  File "/home/quang/Desktop/Python/blog-django/venv/lib/python3.8/site-packages/django/db/models/sql/query.py", line 1562, in _add_q
    child_clause, needed_inner = self.build_filter(
  File "/home/quang/Desktop/Python/blog-django/venv/lib/python3.8/site-packages/django/db/models/sql/query.py", line 1404, in build_filter
    arg, value = filter_expr
ValueError: not enough values to unpack (expected 2, got 1)
2022-08-19 01:49:46 ERROR not enough values to unpack (expected 2, got 1)
Traceback (most recent call last):
  File "/home/quang/Desktop/Python/blog-django/venv/lib/python3.8/site-packages/django/core/handlers/base.py", line 197, in _get_response
    response = wrapped_callback(request, *callback_args, **callback_kwargs)
  File "/usr/lib/python3.8/contextlib.py", line 75, in inner
    return func(*args, **kwds)
  File "/home/quang/Desktop/Python/blog-django/venv/lib/python3.8/site-packages/django/views/decorators/csrf.py", line 54, in wrapped_view
    return view_func(*args, **kwargs)
  File "/home/quang/Desktop/Python/blog-django/venv/lib/python3.8/site-packages/rest_framework/viewsets.py", line 125, in view
    return self.dispatch(request, *args, **kwargs)
  File "/home/quang/Desktop/Python/blog-django/venv/lib/python3.8/site-packages/rest_framework/views.py", line 509, in dispatch
    response = self.handle_exception(exc)
  File "/home/quang/Desktop/Python/blog-django/venv/lib/python3.8/site-packages/rest_framework/views.py", line 469, in handle_exception
    self.raise_uncaught_exception(exc)
  File "/home/quang/Desktop/Python/blog-django/venv/lib/python3.8/site-packages/rest_framework/views.py", line 480, in raise_uncaught_exception
    raise exc
  File "/home/quang/Desktop/Python/blog-django/venv/lib/python3.8/site-packages/rest_framework/views.py", line 506, in dispatch
    response = handler(request, *args, **kwargs)
  File "/home/quang/Desktop/Python/blog-django/apps/api/views/blog_view.py", line 32, in retrieve
    category = get_object_or_404(queryset,pk)
  File "/home/quang/Desktop/Python/blog-django/venv/lib/python3.8/site-packages/django/shortcuts.py", line 85, in get_object_or_404
    return queryset.get(*args, **kwargs)
  File "/home/quang/Desktop/Python/blog-django/venv/lib/python3.8/site-packages/django/db/models/query.py", line 636, in get
    clone = self._chain() if self.query.combinator else self.filter(*args, **kwargs)
  File "/home/quang/Desktop/Python/blog-django/venv/lib/python3.8/site-packages/django/db/models/query.py", line 1420, in filter
    return self._filter_or_exclude(False, args, kwargs)
  File "/home/quang/Desktop/Python/blog-django/venv/lib/python3.8/site-packages/django/db/models/query.py", line 1438, in _filter_or_exclude
    clone._filter_or_exclude_inplace(negate, args, kwargs)
  File "/home/quang/Desktop/Python/blog-django/venv/lib/python3.8/site-packages/django/db/models/query.py", line 1445, in _filter_or_exclude_inplace
    self._query.add_q(Q(*args, **kwargs))
  File "/home/quang/Desktop/Python/blog-django/venv/lib/python3.8/site-packages/django/db/models/sql/query.py", line 1532, in add_q
    clause, _ = self._add_q(q_object, self.used_aliases)
  File "/home/quang/Desktop/Python/blog-django/venv/lib/python3.8/site-packages/django/db/models/sql/query.py", line 1562, in _add_q
    child_clause, needed_inner = self.build_filter(
  File "/home/quang/Desktop/Python/blog-django/venv/lib/python3.8/site-packages/django/db/models/sql/query.py", line 1404, in build_filter
    arg, value = filter_expr
ValueError: not enough values to unpack (expected 2, got 1)
2022-08-19 01:50:10 ERROR not enough values to unpack (expected 2, got 1)
Traceback (most recent call last):
  File "/home/quang/Desktop/Python/blog-django/venv/lib/python3.8/site-packages/django/core/handlers/base.py", line 197, in _get_response
    response = wrapped_callback(request, *callback_args, **callback_kwargs)
  File "/usr/lib/python3.8/contextlib.py", line 75, in inner
    return func(*args, **kwds)
  File "/home/quang/Desktop/Python/blog-django/venv/lib/python3.8/site-packages/django/views/decorators/csrf.py", line 54, in wrapped_view
    return view_func(*args, **kwargs)
  File "/home/quang/Desktop/Python/blog-django/venv/lib/python3.8/site-packages/rest_framework/viewsets.py", line 125, in view
    return self.dispatch(request, *args, **kwargs)
  File "/home/quang/Desktop/Python/blog-django/venv/lib/python3.8/site-packages/rest_framework/views.py", line 509, in dispatch
    response = self.handle_exception(exc)
  File "/home/quang/Desktop/Python/blog-django/venv/lib/python3.8/site-packages/rest_framework/views.py", line 469, in handle_exception
    self.raise_uncaught_exception(exc)
  File "/home/quang/Desktop/Python/blog-django/venv/lib/python3.8/site-packages/rest_framework/views.py", line 480, in raise_uncaught_exception
    raise exc
  File "/home/quang/Desktop/Python/blog-django/venv/lib/python3.8/site-packages/rest_framework/views.py", line 506, in dispatch
    response = handler(request, *args, **kwargs)
  File "/home/quang/Desktop/Python/blog-django/apps/api/views/blog_view.py", line 32, in retrieve
    category = get_object_or_404(queryset,pk)
  File "/home/quang/Desktop/Python/blog-django/venv/lib/python3.8/site-packages/django/shortcuts.py", line 85, in get_object_or_404
    return queryset.get(*args, **kwargs)
  File "/home/quang/Desktop/Python/blog-django/venv/lib/python3.8/site-packages/django/db/models/query.py", line 636, in get
    clone = self._chain() if self.query.combinator else self.filter(*args, **kwargs)
  File "/home/quang/Desktop/Python/blog-django/venv/lib/python3.8/site-packages/django/db/models/query.py", line 1420, in filter
    return self._filter_or_exclude(False, args, kwargs)
  File "/home/quang/Desktop/Python/blog-django/venv/lib/python3.8/site-packages/django/db/models/query.py", line 1438, in _filter_or_exclude
    clone._filter_or_exclude_inplace(negate, args, kwargs)
  File "/home/quang/Desktop/Python/blog-django/venv/lib/python3.8/site-packages/django/db/models/query.py", line 1445, in _filter_or_exclude_inplace
    self._query.add_q(Q(*args, **kwargs))
  File "/home/quang/Desktop/Python/blog-django/venv/lib/python3.8/site-packages/django/db/models/sql/query.py", line 1532, in add_q
    clause, _ = self._add_q(q_object, self.used_aliases)
  File "/home/quang/Desktop/Python/blog-django/venv/lib/python3.8/site-packages/django/db/models/sql/query.py", line 1562, in _add_q
    child_clause, needed_inner = self.build_filter(
  File "/home/quang/Desktop/Python/blog-django/venv/lib/python3.8/site-packages/django/db/models/sql/query.py", line 1404, in build_filter
    arg, value = filter_expr
ValueError: not enough values to unpack (expected 2, got 1)
2022-08-19 01:50:35 ERROR not enough values to unpack (expected 2, got 1)
Traceback (most recent call last):
  File "/home/quang/Desktop/Python/blog-django/venv/lib/python3.8/site-packages/django/core/handlers/base.py", line 197, in _get_response
    response = wrapped_callback(request, *callback_args, **callback_kwargs)
  File "/usr/lib/python3.8/contextlib.py", line 75, in inner
    return func(*args, **kwds)
  File "/home/quang/Desktop/Python/blog-django/venv/lib/python3.8/site-packages/django/views/decorators/csrf.py", line 54, in wrapped_view
    return view_func(*args, **kwargs)
  File "/home/quang/Desktop/Python/blog-django/venv/lib/python3.8/site-packages/rest_framework/viewsets.py", line 125, in view
    return self.dispatch(request, *args, **kwargs)
  File "/home/quang/Desktop/Python/blog-django/venv/lib/python3.8/site-packages/rest_framework/views.py", line 509, in dispatch
    response = self.handle_exception(exc)
  File "/home/quang/Desktop/Python/blog-django/venv/lib/python3.8/site-packages/rest_framework/views.py", line 469, in handle_exception
    self.raise_uncaught_exception(exc)
  File "/home/quang/Desktop/Python/blog-django/venv/lib/python3.8/site-packages/rest_framework/views.py", line 480, in raise_uncaught_exception
    raise exc
  File "/home/quang/Desktop/Python/blog-django/venv/lib/python3.8/site-packages/rest_framework/views.py", line 506, in dispatch
    response = handler(request, *args, **kwargs)
  File "/home/quang/Desktop/Python/blog-django/apps/api/views/blog_view.py", line 32, in retrieve
    category = get_object_or_404(queryset,pk)
  File "/home/quang/Desktop/Python/blog-django/venv/lib/python3.8/site-packages/django/shortcuts.py", line 85, in get_object_or_404
    return queryset.get(*args, **kwargs)
  File "/home/quang/Desktop/Python/blog-django/venv/lib/python3.8/site-packages/django/db/models/query.py", line 636, in get
    clone = self._chain() if self.query.combinator else self.filter(*args, **kwargs)
  File "/home/quang/Desktop/Python/blog-django/venv/lib/python3.8/site-packages/django/db/models/query.py", line 1420, in filter
    return self._filter_or_exclude(False, args, kwargs)
  File "/home/quang/Desktop/Python/blog-django/venv/lib/python3.8/site-packages/django/db/models/query.py", line 1438, in _filter_or_exclude
    clone._filter_or_exclude_inplace(negate, args, kwargs)
  File "/home/quang/Desktop/Python/blog-django/venv/lib/python3.8/site-packages/django/db/models/query.py", line 1445, in _filter_or_exclude_inplace
    self._query.add_q(Q(*args, **kwargs))
  File "/home/quang/Desktop/Python/blog-django/venv/lib/python3.8/site-packages/django/db/models/sql/query.py", line 1532, in add_q
    clause, _ = self._add_q(q_object, self.used_aliases)
  File "/home/quang/Desktop/Python/blog-django/venv/lib/python3.8/site-packages/django/db/models/sql/query.py", line 1562, in _add_q
    child_clause, needed_inner = self.build_filter(
  File "/home/quang/Desktop/Python/blog-django/venv/lib/python3.8/site-packages/django/db/models/sql/query.py", line 1404, in build_filter
    arg, value = filter_expr
ValueError: not enough values to unpack (expected 2, got 1)
2022-08-19 01:51:32 ERROR not enough values to unpack (expected 2, got 1)
Traceback (most recent call last):
  File "/home/quang/Desktop/Python/blog-django/venv/lib/python3.8/site-packages/django/core/handlers/base.py", line 197, in _get_response
    response = wrapped_callback(request, *callback_args, **callback_kwargs)
  File "/usr/lib/python3.8/contextlib.py", line 75, in inner
    return func(*args, **kwds)
  File "/home/quang/Desktop/Python/blog-django/venv/lib/python3.8/site-packages/django/views/decorators/csrf.py", line 54, in wrapped_view
    return view_func(*args, **kwargs)
  File "/home/quang/Desktop/Python/blog-django/venv/lib/python3.8/site-packages/rest_framework/viewsets.py", line 125, in view
    return self.dispatch(request, *args, **kwargs)
  File "/home/quang/Desktop/Python/blog-django/venv/lib/python3.8/site-packages/rest_framework/views.py", line 509, in dispatch
    response = self.handle_exception(exc)
  File "/home/quang/Desktop/Python/blog-django/venv/lib/python3.8/site-packages/rest_framework/views.py", line 469, in handle_exception
    self.raise_uncaught_exception(exc)
  File "/home/quang/Desktop/Python/blog-django/venv/lib/python3.8/site-packages/rest_framework/views.py", line 480, in raise_uncaught_exception
    raise exc
  File "/home/quang/Desktop/Python/blog-django/venv/lib/python3.8/site-packages/rest_framework/views.py", line 506, in dispatch
    response = handler(request, *args, **kwargs)
  File "/home/quang/Desktop/Python/blog-django/apps/api/views/blog_view.py", line 32, in retrieve
    category = get_object_or_404(query,pk)
  File "/home/quang/Desktop/Python/blog-django/venv/lib/python3.8/site-packages/django/shortcuts.py", line 85, in get_object_or_404
    return queryset.get(*args, **kwargs)
  File "/home/quang/Desktop/Python/blog-django/venv/lib/python3.8/site-packages/django/db/models/query.py", line 636, in get
    clone = self._chain() if self.query.combinator else self.filter(*args, **kwargs)
  File "/home/quang/Desktop/Python/blog-django/venv/lib/python3.8/site-packages/django/db/models/query.py", line 1420, in filter
    return self._filter_or_exclude(False, args, kwargs)
  File "/home/quang/Desktop/Python/blog-django/venv/lib/python3.8/site-packages/django/db/models/query.py", line 1438, in _filter_or_exclude
    clone._filter_or_exclude_inplace(negate, args, kwargs)
  File "/home/quang/Desktop/Python/blog-django/venv/lib/python3.8/site-packages/django/db/models/query.py", line 1445, in _filter_or_exclude_inplace
    self._query.add_q(Q(*args, **kwargs))
  File "/home/quang/Desktop/Python/blog-django/venv/lib/python3.8/site-packages/django/db/models/sql/query.py", line 1532, in add_q
    clause, _ = self._add_q(q_object, self.used_aliases)
  File "/home/quang/Desktop/Python/blog-django/venv/lib/python3.8/site-packages/django/db/models/sql/query.py", line 1562, in _add_q
    child_clause, needed_inner = self.build_filter(
  File "/home/quang/Desktop/Python/blog-django/venv/lib/python3.8/site-packages/django/db/models/sql/query.py", line 1404, in build_filter
    arg, value = filter_expr
ValueError: not enough values to unpack (expected 2, got 1)
2022-08-19 01:52:09 ERROR local variable 'message' referenced before assignment
Traceback (most recent call last):
  File "/home/quang/Desktop/Python/blog-django/venv/lib/python3.8/site-packages/django/shortcuts.py", line 85, in get_object_or_404
    return queryset.get(*args, **kwargs)
  File "/home/quang/Desktop/Python/blog-django/venv/lib/python3.8/site-packages/django/db/models/query.py", line 650, in get
    raise self.model.DoesNotExist(
apps.api.models.blog_model.Category.DoesNotExist: Category matching query does not exist.

During handling of the above exception, another exception occurred:

Traceback (most recent call last):
  File "/home/quang/Desktop/Python/blog-django/venv/lib/python3.8/site-packages/rest_framework/views.py", line 506, in dispatch
    response = handler(request, *args, **kwargs)
  File "/home/quang/Desktop/Python/blog-django/apps/api/views/blog_view.py", line 32, in retrieve
    category = get_object_or_404(query,pk=pk)
  File "/home/quang/Desktop/Python/blog-django/venv/lib/python3.8/site-packages/django/shortcuts.py", line 87, in get_object_or_404
    raise Http404(
django.http.response.Http404: No Category matches the given query.

During handling of the above exception, another exception occurred:

Traceback (most recent call last):
  File "/home/quang/Desktop/Python/blog-django/venv/lib/python3.8/site-packages/django/core/handlers/base.py", line 197, in _get_response
    response = wrapped_callback(request, *callback_args, **callback_kwargs)
  File "/usr/lib/python3.8/contextlib.py", line 75, in inner
    return func(*args, **kwds)
  File "/home/quang/Desktop/Python/blog-django/venv/lib/python3.8/site-packages/django/views/decorators/csrf.py", line 54, in wrapped_view
    return view_func(*args, **kwargs)
  File "/home/quang/Desktop/Python/blog-django/venv/lib/python3.8/site-packages/rest_framework/viewsets.py", line 125, in view
    return self.dispatch(request, *args, **kwargs)
  File "/home/quang/Desktop/Python/blog-django/venv/lib/python3.8/site-packages/rest_framework/views.py", line 509, in dispatch
    response = self.handle_exception(exc)
  File "/home/quang/Desktop/Python/blog-django/venv/lib/python3.8/site-packages/rest_framework/views.py", line 466, in handle_exception
    response = exception_handler(exc, context)
  File "/home/quang/Desktop/Python/blog-django/libs/rest_framework/exc_handler.py", line 45, in custom_exception_handler
    'message': message,
UnboundLocalError: local variable 'message' referenced before assignment
2022-08-19 09:34:00 ERROR retrieve() got an unexpected keyword argument 'pk'
Traceback (most recent call last):
  File "/home/quang/Desktop/Python/blog-django/venv/lib/python3.8/site-packages/django/core/handlers/base.py", line 197, in _get_response
    response = wrapped_callback(request, *callback_args, **callback_kwargs)
  File "/usr/lib/python3.8/contextlib.py", line 75, in inner
    return func(*args, **kwds)
  File "/home/quang/Desktop/Python/blog-django/venv/lib/python3.8/site-packages/django/views/decorators/csrf.py", line 54, in wrapped_view
    return view_func(*args, **kwargs)
  File "/home/quang/Desktop/Python/blog-django/venv/lib/python3.8/site-packages/rest_framework/viewsets.py", line 125, in view
    return self.dispatch(request, *args, **kwargs)
  File "/home/quang/Desktop/Python/blog-django/venv/lib/python3.8/site-packages/rest_framework/views.py", line 509, in dispatch
    response = self.handle_exception(exc)
  File "/home/quang/Desktop/Python/blog-django/venv/lib/python3.8/site-packages/rest_framework/views.py", line 469, in handle_exception
    self.raise_uncaught_exception(exc)
  File "/home/quang/Desktop/Python/blog-django/venv/lib/python3.8/site-packages/rest_framework/views.py", line 480, in raise_uncaught_exception
    raise exc
  File "/home/quang/Desktop/Python/blog-django/venv/lib/python3.8/site-packages/rest_framework/views.py", line 506, in dispatch
    response = handler(request, *args, **kwargs)
TypeError: retrieve() got an unexpected keyword argument 'pk'
2022-08-19 09:34:31 ERROR retrieve() got an unexpected keyword argument 'pk'
Traceback (most recent call last):
  File "/home/quang/Desktop/Python/blog-django/venv/lib/python3.8/site-packages/django/core/handlers/base.py", line 197, in _get_response
    response = wrapped_callback(request, *callback_args, **callback_kwargs)
  File "/usr/lib/python3.8/contextlib.py", line 75, in inner
    return func(*args, **kwds)
  File "/home/quang/Desktop/Python/blog-django/venv/lib/python3.8/site-packages/django/views/decorators/csrf.py", line 54, in wrapped_view
    return view_func(*args, **kwargs)
  File "/home/quang/Desktop/Python/blog-django/venv/lib/python3.8/site-packages/rest_framework/viewsets.py", line 125, in view
    return self.dispatch(request, *args, **kwargs)
  File "/home/quang/Desktop/Python/blog-django/venv/lib/python3.8/site-packages/rest_framework/views.py", line 509, in dispatch
    response = self.handle_exception(exc)
  File "/home/quang/Desktop/Python/blog-django/venv/lib/python3.8/site-packages/rest_framework/views.py", line 469, in handle_exception
    self.raise_uncaught_exception(exc)
  File "/home/quang/Desktop/Python/blog-django/venv/lib/python3.8/site-packages/rest_framework/views.py", line 480, in raise_uncaught_exception
    raise exc
  File "/home/quang/Desktop/Python/blog-django/venv/lib/python3.8/site-packages/rest_framework/views.py", line 506, in dispatch
    response = handler(request, *args, **kwargs)
TypeError: retrieve() got an unexpected keyword argument 'pk'
2022-08-19 09:34:51 ERROR Field 'id' expected a number but got 'bootrap-frontend'.
Traceback (most recent call last):
  File "/home/quang/Desktop/Python/blog-django/venv/lib/python3.8/site-packages/django/db/models/fields/__init__.py", line 2018, in get_prep_value
    return int(value)
ValueError: invalid literal for int() with base 10: 'bootrap-frontend'

The above exception was the direct cause of the following exception:

Traceback (most recent call last):
  File "/home/quang/Desktop/Python/blog-django/venv/lib/python3.8/site-packages/django/core/handlers/base.py", line 197, in _get_response
    response = wrapped_callback(request, *callback_args, **callback_kwargs)
  File "/usr/lib/python3.8/contextlib.py", line 75, in inner
    return func(*args, **kwds)
  File "/home/quang/Desktop/Python/blog-django/venv/lib/python3.8/site-packages/django/views/decorators/csrf.py", line 54, in wrapped_view
    return view_func(*args, **kwargs)
  File "/home/quang/Desktop/Python/blog-django/venv/lib/python3.8/site-packages/rest_framework/viewsets.py", line 125, in view
    return self.dispatch(request, *args, **kwargs)
  File "/home/quang/Desktop/Python/blog-django/venv/lib/python3.8/site-packages/rest_framework/views.py", line 509, in dispatch
    response = self.handle_exception(exc)
  File "/home/quang/Desktop/Python/blog-django/venv/lib/python3.8/site-packages/rest_framework/views.py", line 469, in handle_exception
    self.raise_uncaught_exception(exc)
  File "/home/quang/Desktop/Python/blog-django/venv/lib/python3.8/site-packages/rest_framework/views.py", line 480, in raise_uncaught_exception
    raise exc
  File "/home/quang/Desktop/Python/blog-django/venv/lib/python3.8/site-packages/rest_framework/views.py", line 506, in dispatch
    response = handler(request, *args, **kwargs)
  File "/home/quang/Desktop/Python/blog-django/apps/api/views/blog_view.py", line 59, in retrieve
    post = Post.objects.filter(filter_post)
  File "/home/quang/Desktop/Python/blog-django/venv/lib/python3.8/site-packages/django/db/models/manager.py", line 85, in manager_method
    return getattr(self.get_queryset(), name)(*args, **kwargs)
  File "/home/quang/Desktop/Python/blog-django/venv/lib/python3.8/site-packages/django/db/models/query.py", line 1420, in filter
    return self._filter_or_exclude(False, args, kwargs)
  File "/home/quang/Desktop/Python/blog-django/venv/lib/python3.8/site-packages/django/db/models/query.py", line 1438, in _filter_or_exclude
    clone._filter_or_exclude_inplace(negate, args, kwargs)
  File "/home/quang/Desktop/Python/blog-django/venv/lib/python3.8/site-packages/django/db/models/query.py", line 1445, in _filter_or_exclude_inplace
    self._query.add_q(Q(*args, **kwargs))
  File "/home/quang/Desktop/Python/blog-django/venv/lib/python3.8/site-packages/django/db/models/sql/query.py", line 1532, in add_q
    clause, _ = self._add_q(q_object, self.used_aliases)
  File "/home/quang/Desktop/Python/blog-django/venv/lib/python3.8/site-packages/django/db/models/sql/query.py", line 1562, in _add_q
    child_clause, needed_inner = self.build_filter(
  File "/home/quang/Desktop/Python/blog-django/venv/lib/python3.8/site-packages/django/db/models/sql/query.py", line 1388, in build_filter
    return self._add_q(
  File "/home/quang/Desktop/Python/blog-django/venv/lib/python3.8/site-packages/django/db/models/sql/query.py", line 1562, in _add_q
    child_clause, needed_inner = self.build_filter(
  File "/home/quang/Desktop/Python/blog-django/venv/lib/python3.8/site-packages/django/db/models/sql/query.py", line 1478, in build_filter
    condition = self.build_lookup(lookups, col, value)
  File "/home/quang/Desktop/Python/blog-django/venv/lib/python3.8/site-packages/django/db/models/sql/query.py", line 1303, in build_lookup
    lookup = lookup_class(lhs, rhs)
  File "/home/quang/Desktop/Python/blog-django/venv/lib/python3.8/site-packages/django/db/models/lookups.py", line 27, in __init__
    self.rhs = self.get_prep_lookup()
  File "/home/quang/Desktop/Python/blog-django/venv/lib/python3.8/site-packages/django/db/models/lookups.py", line 341, in get_prep_lookup
    return super().get_prep_lookup()
  File "/home/quang/Desktop/Python/blog-django/venv/lib/python3.8/site-packages/django/db/models/lookups.py", line 85, in get_prep_lookup
    return self.lhs.output_field.get_prep_value(self.rhs)
  File "/home/quang/Desktop/Python/blog-django/venv/lib/python3.8/site-packages/django/db/models/fields/__init__.py", line 2020, in get_prep_value
    raise e.__class__(
ValueError: Field 'id' expected a number but got 'bootrap-frontend'.
2022-08-19 09:34:56 ERROR Got AttributeError when attempting to get a value for field `category` on serializer `PostSerializer`.
The serializer field might be named incorrectly and not match any attribute or key on the `QuerySet` instance.
Original exception text was: 'QuerySet' object has no attribute 'category'.
Traceback (most recent call last):
  File "/home/quang/Desktop/Python/blog-django/venv/lib/python3.8/site-packages/rest_framework/fields.py", line 457, in get_attribute
    return get_attribute(instance, self.source_attrs)
  File "/home/quang/Desktop/Python/blog-django/venv/lib/python3.8/site-packages/rest_framework/fields.py", line 97, in get_attribute
    instance = getattr(instance, attr)
AttributeError: 'QuerySet' object has no attribute 'category'

During handling of the above exception, another exception occurred:

Traceback (most recent call last):
  File "/home/quang/Desktop/Python/blog-django/venv/lib/python3.8/site-packages/django/core/handlers/base.py", line 197, in _get_response
    response = wrapped_callback(request, *callback_args, **callback_kwargs)
  File "/usr/lib/python3.8/contextlib.py", line 75, in inner
    return func(*args, **kwds)
  File "/home/quang/Desktop/Python/blog-django/venv/lib/python3.8/site-packages/django/views/decorators/csrf.py", line 54, in wrapped_view
    return view_func(*args, **kwargs)
  File "/home/quang/Desktop/Python/blog-django/venv/lib/python3.8/site-packages/rest_framework/viewsets.py", line 125, in view
    return self.dispatch(request, *args, **kwargs)
  File "/home/quang/Desktop/Python/blog-django/venv/lib/python3.8/site-packages/rest_framework/views.py", line 509, in dispatch
    response = self.handle_exception(exc)
  File "/home/quang/Desktop/Python/blog-django/venv/lib/python3.8/site-packages/rest_framework/views.py", line 469, in handle_exception
    self.raise_uncaught_exception(exc)
  File "/home/quang/Desktop/Python/blog-django/venv/lib/python3.8/site-packages/rest_framework/views.py", line 480, in raise_uncaught_exception
    raise exc
  File "/home/quang/Desktop/Python/blog-django/venv/lib/python3.8/site-packages/rest_framework/views.py", line 506, in dispatch
    response = handler(request, *args, **kwargs)
  File "/home/quang/Desktop/Python/blog-django/apps/api/views/blog_view.py", line 61, in retrieve
    return Response(serializer.data,status=status.HTTP_200_OK)
  File "/home/quang/Desktop/Python/blog-django/venv/lib/python3.8/site-packages/rest_framework/serializers.py", line 555, in data
    ret = super().data
  File "/home/quang/Desktop/Python/blog-django/venv/lib/python3.8/site-packages/rest_framework/serializers.py", line 253, in data
    self._data = self.to_representation(self.instance)
  File "/home/quang/Desktop/Python/blog-django/venv/lib/python3.8/site-packages/rest_framework/serializers.py", line 509, in to_representation
    attribute = field.get_attribute(instance)
  File "/home/quang/Desktop/Python/blog-django/venv/lib/python3.8/site-packages/rest_framework/relations.py", line 190, in get_attribute
    return super().get_attribute(instance)
  File "/home/quang/Desktop/Python/blog-django/venv/lib/python3.8/site-packages/rest_framework/fields.py", line 490, in get_attribute
    raise type(exc)(msg)
AttributeError: Got AttributeError when attempting to get a value for field `category` on serializer `PostSerializer`.
The serializer field might be named incorrectly and not match any attribute or key on the `QuerySet` instance.
Original exception text was: 'QuerySet' object has no attribute 'category'.
2022-08-19 09:36:37 ERROR Got AttributeError when attempting to get a value for field `author` on serializer `PostSerializer`.
The serializer field might be named incorrectly and not match any attribute or key on the `QuerySet` instance.
Original exception text was: 'QuerySet' object has no attribute 'author'.
Traceback (most recent call last):
  File "/home/quang/Desktop/Python/blog-django/venv/lib/python3.8/site-packages/rest_framework/fields.py", line 457, in get_attribute
    return get_attribute(instance, self.source_attrs)
  File "/home/quang/Desktop/Python/blog-django/venv/lib/python3.8/site-packages/rest_framework/fields.py", line 97, in get_attribute
    instance = getattr(instance, attr)
AttributeError: 'QuerySet' object has no attribute 'author'

During handling of the above exception, another exception occurred:

Traceback (most recent call last):
  File "/home/quang/Desktop/Python/blog-django/venv/lib/python3.8/site-packages/django/core/handlers/base.py", line 197, in _get_response
    response = wrapped_callback(request, *callback_args, **callback_kwargs)
  File "/usr/lib/python3.8/contextlib.py", line 75, in inner
    return func(*args, **kwds)
  File "/home/quang/Desktop/Python/blog-django/venv/lib/python3.8/site-packages/django/views/decorators/csrf.py", line 54, in wrapped_view
    return view_func(*args, **kwargs)
  File "/home/quang/Desktop/Python/blog-django/venv/lib/python3.8/site-packages/rest_framework/viewsets.py", line 125, in view
    return self.dispatch(request, *args, **kwargs)
  File "/home/quang/Desktop/Python/blog-django/venv/lib/python3.8/site-packages/rest_framework/views.py", line 509, in dispatch
    response = self.handle_exception(exc)
  File "/home/quang/Desktop/Python/blog-django/venv/lib/python3.8/site-packages/rest_framework/views.py", line 469, in handle_exception
    self.raise_uncaught_exception(exc)
  File "/home/quang/Desktop/Python/blog-django/venv/lib/python3.8/site-packages/rest_framework/views.py", line 480, in raise_uncaught_exception
    raise exc
  File "/home/quang/Desktop/Python/blog-django/venv/lib/python3.8/site-packages/rest_framework/views.py", line 506, in dispatch
    response = handler(request, *args, **kwargs)
  File "/home/quang/Desktop/Python/blog-django/apps/api/views/blog_view.py", line 61, in retrieve
    return Response(serializer.data,status=status.HTTP_200_OK)
  File "/home/quang/Desktop/Python/blog-django/venv/lib/python3.8/site-packages/rest_framework/serializers.py", line 555, in data
    ret = super().data
  File "/home/quang/Desktop/Python/blog-django/venv/lib/python3.8/site-packages/rest_framework/serializers.py", line 253, in data
    self._data = self.to_representation(self.instance)
  File "/home/quang/Desktop/Python/blog-django/venv/lib/python3.8/site-packages/rest_framework/serializers.py", line 509, in to_representation
    attribute = field.get_attribute(instance)
  File "/home/quang/Desktop/Python/blog-django/venv/lib/python3.8/site-packages/rest_framework/relations.py", line 190, in get_attribute
    return super().get_attribute(instance)
  File "/home/quang/Desktop/Python/blog-django/venv/lib/python3.8/site-packages/rest_framework/fields.py", line 490, in get_attribute
    raise type(exc)(msg)
AttributeError: Got AttributeError when attempting to get a value for field `author` on serializer `PostSerializer`.
The serializer field might be named incorrectly and not match any attribute or key on the `QuerySet` instance.
Original exception text was: 'QuerySet' object has no attribute 'author'.
2022-08-19 09:36:40 ERROR Got AttributeError when attempting to get a value for field `author` on serializer `PostSerializer`.
The serializer field might be named incorrectly and not match any attribute or key on the `QuerySet` instance.
Original exception text was: 'QuerySet' object has no attribute 'author'.
Traceback (most recent call last):
  File "/home/quang/Desktop/Python/blog-django/venv/lib/python3.8/site-packages/rest_framework/fields.py", line 457, in get_attribute
    return get_attribute(instance, self.source_attrs)
  File "/home/quang/Desktop/Python/blog-django/venv/lib/python3.8/site-packages/rest_framework/fields.py", line 97, in get_attribute
    instance = getattr(instance, attr)
AttributeError: 'QuerySet' object has no attribute 'author'

During handling of the above exception, another exception occurred:

Traceback (most recent call last):
  File "/home/quang/Desktop/Python/blog-django/venv/lib/python3.8/site-packages/django/core/handlers/base.py", line 197, in _get_response
    response = wrapped_callback(request, *callback_args, **callback_kwargs)
  File "/usr/lib/python3.8/contextlib.py", line 75, in inner
    return func(*args, **kwds)
  File "/home/quang/Desktop/Python/blog-django/venv/lib/python3.8/site-packages/django/views/decorators/csrf.py", line 54, in wrapped_view
    return view_func(*args, **kwargs)
  File "/home/quang/Desktop/Python/blog-django/venv/lib/python3.8/site-packages/rest_framework/viewsets.py", line 125, in view
    return self.dispatch(request, *args, **kwargs)
  File "/home/quang/Desktop/Python/blog-django/venv/lib/python3.8/site-packages/rest_framework/views.py", line 509, in dispatch
    response = self.handle_exception(exc)
  File "/home/quang/Desktop/Python/blog-django/venv/lib/python3.8/site-packages/rest_framework/views.py", line 469, in handle_exception
    self.raise_uncaught_exception(exc)
  File "/home/quang/Desktop/Python/blog-django/venv/lib/python3.8/site-packages/rest_framework/views.py", line 480, in raise_uncaught_exception
    raise exc
  File "/home/quang/Desktop/Python/blog-django/venv/lib/python3.8/site-packages/rest_framework/views.py", line 506, in dispatch
    response = handler(request, *args, **kwargs)
  File "/home/quang/Desktop/Python/blog-django/apps/api/views/blog_view.py", line 61, in retrieve
    return Response(serializer.data,status=status.HTTP_200_OK)
  File "/home/quang/Desktop/Python/blog-django/venv/lib/python3.8/site-packages/rest_framework/serializers.py", line 555, in data
    ret = super().data
  File "/home/quang/Desktop/Python/blog-django/venv/lib/python3.8/site-packages/rest_framework/serializers.py", line 253, in data
    self._data = self.to_representation(self.instance)
  File "/home/quang/Desktop/Python/blog-django/venv/lib/python3.8/site-packages/rest_framework/serializers.py", line 509, in to_representation
    attribute = field.get_attribute(instance)
  File "/home/quang/Desktop/Python/blog-django/venv/lib/python3.8/site-packages/rest_framework/relations.py", line 190, in get_attribute
    return super().get_attribute(instance)
  File "/home/quang/Desktop/Python/blog-django/venv/lib/python3.8/site-packages/rest_framework/fields.py", line 490, in get_attribute
    raise type(exc)(msg)
AttributeError: Got AttributeError when attempting to get a value for field `author` on serializer `PostSerializer`.
The serializer field might be named incorrectly and not match any attribute or key on the `QuerySet` instance.
Original exception text was: 'QuerySet' object has no attribute 'author'.
2022-08-19 09:38:24 ERROR Got AttributeError when attempting to get a value for field `category` on serializer `PostSerializer`.
The serializer field might be named incorrectly and not match any attribute or key on the `QuerySet` instance.
Original exception text was: 'QuerySet' object has no attribute 'category'.
Traceback (most recent call last):
  File "/home/quang/Desktop/Python/blog-django/venv/lib/python3.8/site-packages/rest_framework/fields.py", line 457, in get_attribute
    return get_attribute(instance, self.source_attrs)
  File "/home/quang/Desktop/Python/blog-django/venv/lib/python3.8/site-packages/rest_framework/fields.py", line 97, in get_attribute
    instance = getattr(instance, attr)
AttributeError: 'QuerySet' object has no attribute 'category'

During handling of the above exception, another exception occurred:

Traceback (most recent call last):
  File "/home/quang/Desktop/Python/blog-django/venv/lib/python3.8/site-packages/django/core/handlers/base.py", line 197, in _get_response
    response = wrapped_callback(request, *callback_args, **callback_kwargs)
  File "/usr/lib/python3.8/contextlib.py", line 75, in inner
    return func(*args, **kwds)
  File "/home/quang/Desktop/Python/blog-django/venv/lib/python3.8/site-packages/django/views/decorators/csrf.py", line 54, in wrapped_view
    return view_func(*args, **kwargs)
  File "/home/quang/Desktop/Python/blog-django/venv/lib/python3.8/site-packages/rest_framework/viewsets.py", line 125, in view
    return self.dispatch(request, *args, **kwargs)
  File "/home/quang/Desktop/Python/blog-django/venv/lib/python3.8/site-packages/rest_framework/views.py", line 509, in dispatch
    response = self.handle_exception(exc)
  File "/home/quang/Desktop/Python/blog-django/venv/lib/python3.8/site-packages/rest_framework/views.py", line 469, in handle_exception
    self.raise_uncaught_exception(exc)
  File "/home/quang/Desktop/Python/blog-django/venv/lib/python3.8/site-packages/rest_framework/views.py", line 480, in raise_uncaught_exception
    raise exc
  File "/home/quang/Desktop/Python/blog-django/venv/lib/python3.8/site-packages/rest_framework/views.py", line 506, in dispatch
    response = handler(request, *args, **kwargs)
  File "/home/quang/Desktop/Python/blog-django/apps/api/views/blog_view.py", line 61, in retrieve
    return Response(serializer.data,status=status.HTTP_200_OK)
  File "/home/quang/Desktop/Python/blog-django/venv/lib/python3.8/site-packages/rest_framework/serializers.py", line 555, in data
    ret = super().data
  File "/home/quang/Desktop/Python/blog-django/venv/lib/python3.8/site-packages/rest_framework/serializers.py", line 253, in data
    self._data = self.to_representation(self.instance)
  File "/home/quang/Desktop/Python/blog-django/venv/lib/python3.8/site-packages/rest_framework/serializers.py", line 509, in to_representation
    attribute = field.get_attribute(instance)
  File "/home/quang/Desktop/Python/blog-django/venv/lib/python3.8/site-packages/rest_framework/relations.py", line 190, in get_attribute
    return super().get_attribute(instance)
  File "/home/quang/Desktop/Python/blog-django/venv/lib/python3.8/site-packages/rest_framework/fields.py", line 490, in get_attribute
    raise type(exc)(msg)
AttributeError: Got AttributeError when attempting to get a value for field `category` on serializer `PostSerializer`.
The serializer field might be named incorrectly and not match any attribute or key on the `QuerySet` instance.
Original exception text was: 'QuerySet' object has no attribute 'category'.
2022-08-19 09:39:05 ERROR Got AttributeError when attempting to get a value for field `name` on serializer `PostSerializer`.
The serializer field might be named incorrectly and not match any attribute or key on the `QuerySet` instance.
Original exception text was: 'QuerySet' object has no attribute 'name'.
Traceback (most recent call last):
  File "/home/quang/Desktop/Python/blog-django/venv/lib/python3.8/site-packages/rest_framework/fields.py", line 457, in get_attribute
    return get_attribute(instance, self.source_attrs)
  File "/home/quang/Desktop/Python/blog-django/venv/lib/python3.8/site-packages/rest_framework/fields.py", line 97, in get_attribute
    instance = getattr(instance, attr)
AttributeError: 'QuerySet' object has no attribute 'name'

During handling of the above exception, another exception occurred:

Traceback (most recent call last):
  File "/home/quang/Desktop/Python/blog-django/venv/lib/python3.8/site-packages/django/core/handlers/base.py", line 197, in _get_response
    response = wrapped_callback(request, *callback_args, **callback_kwargs)
  File "/usr/lib/python3.8/contextlib.py", line 75, in inner
    return func(*args, **kwds)
  File "/home/quang/Desktop/Python/blog-django/venv/lib/python3.8/site-packages/django/views/decorators/csrf.py", line 54, in wrapped_view
    return view_func(*args, **kwargs)
  File "/home/quang/Desktop/Python/blog-django/venv/lib/python3.8/site-packages/rest_framework/viewsets.py", line 125, in view
    return self.dispatch(request, *args, **kwargs)
  File "/home/quang/Desktop/Python/blog-django/venv/lib/python3.8/site-packages/rest_framework/views.py", line 509, in dispatch
    response = self.handle_exception(exc)
  File "/home/quang/Desktop/Python/blog-django/venv/lib/python3.8/site-packages/rest_framework/views.py", line 469, in handle_exception
    self.raise_uncaught_exception(exc)
  File "/home/quang/Desktop/Python/blog-django/venv/lib/python3.8/site-packages/rest_framework/views.py", line 480, in raise_uncaught_exception
    raise exc
  File "/home/quang/Desktop/Python/blog-django/venv/lib/python3.8/site-packages/rest_framework/views.py", line 506, in dispatch
    response = handler(request, *args, **kwargs)
  File "/home/quang/Desktop/Python/blog-django/apps/api/views/blog_view.py", line 61, in retrieve
    return Response(serializer.data,status=status.HTTP_200_OK)
  File "/home/quang/Desktop/Python/blog-django/venv/lib/python3.8/site-packages/rest_framework/serializers.py", line 555, in data
    ret = super().data
  File "/home/quang/Desktop/Python/blog-django/venv/lib/python3.8/site-packages/rest_framework/serializers.py", line 253, in data
    self._data = self.to_representation(self.instance)
  File "/home/quang/Desktop/Python/blog-django/venv/lib/python3.8/site-packages/rest_framework/serializers.py", line 509, in to_representation
    attribute = field.get_attribute(instance)
  File "/home/quang/Desktop/Python/blog-django/venv/lib/python3.8/site-packages/rest_framework/fields.py", line 490, in get_attribute
    raise type(exc)(msg)
AttributeError: Got AttributeError when attempting to get a value for field `name` on serializer `PostSerializer`.
The serializer field might be named incorrectly and not match any attribute or key on the `QuerySet` instance.
Original exception text was: 'QuerySet' object has no attribute 'name'.
2022-08-19 09:39:46 ERROR Got AttributeError when attempting to get a value for field `name` on serializer `PostSerializer`.
The serializer field might be named incorrectly and not match any attribute or key on the `QuerySet` instance.
Original exception text was: 'QuerySet' object has no attribute 'name'.
Traceback (most recent call last):
  File "/home/quang/Desktop/Python/blog-django/venv/lib/python3.8/site-packages/rest_framework/fields.py", line 457, in get_attribute
    return get_attribute(instance, self.source_attrs)
  File "/home/quang/Desktop/Python/blog-django/venv/lib/python3.8/site-packages/rest_framework/fields.py", line 97, in get_attribute
    instance = getattr(instance, attr)
AttributeError: 'QuerySet' object has no attribute 'name'

During handling of the above exception, another exception occurred:

Traceback (most recent call last):
  File "/home/quang/Desktop/Python/blog-django/venv/lib/python3.8/site-packages/django/core/handlers/base.py", line 197, in _get_response
    response = wrapped_callback(request, *callback_args, **callback_kwargs)
  File "/usr/lib/python3.8/contextlib.py", line 75, in inner
    return func(*args, **kwds)
  File "/home/quang/Desktop/Python/blog-django/venv/lib/python3.8/site-packages/django/views/decorators/csrf.py", line 54, in wrapped_view
    return view_func(*args, **kwargs)
  File "/home/quang/Desktop/Python/blog-django/venv/lib/python3.8/site-packages/rest_framework/viewsets.py", line 125, in view
    return self.dispatch(request, *args, **kwargs)
  File "/home/quang/Desktop/Python/blog-django/venv/lib/python3.8/site-packages/rest_framework/views.py", line 509, in dispatch
    response = self.handle_exception(exc)
  File "/home/quang/Desktop/Python/blog-django/venv/lib/python3.8/site-packages/rest_framework/views.py", line 469, in handle_exception
    self.raise_uncaught_exception(exc)
  File "/home/quang/Desktop/Python/blog-django/venv/lib/python3.8/site-packages/rest_framework/views.py", line 480, in raise_uncaught_exception
    raise exc
  File "/home/quang/Desktop/Python/blog-django/venv/lib/python3.8/site-packages/rest_framework/views.py", line 506, in dispatch
    response = handler(request, *args, **kwargs)
  File "/home/quang/Desktop/Python/blog-django/apps/api/views/blog_view.py", line 61, in retrieve
    return Response(serializer.data,status=status.HTTP_200_OK)
  File "/home/quang/Desktop/Python/blog-django/venv/lib/python3.8/site-packages/rest_framework/serializers.py", line 555, in data
    ret = super().data
  File "/home/quang/Desktop/Python/blog-django/venv/lib/python3.8/site-packages/rest_framework/serializers.py", line 253, in data
    self._data = self.to_representation(self.instance)
  File "/home/quang/Desktop/Python/blog-django/venv/lib/python3.8/site-packages/rest_framework/serializers.py", line 509, in to_representation
    attribute = field.get_attribute(instance)
  File "/home/quang/Desktop/Python/blog-django/venv/lib/python3.8/site-packages/rest_framework/fields.py", line 490, in get_attribute
    raise type(exc)(msg)
AttributeError: Got AttributeError when attempting to get a value for field `name` on serializer `PostSerializer`.
The serializer field might be named incorrectly and not match any attribute or key on the `QuerySet` instance.
Original exception text was: 'QuerySet' object has no attribute 'name'.
2022-08-19 09:40:29 ERROR Got AttributeError when attempting to get a value for field `name` on serializer `PostSerializer`.
The serializer field might be named incorrectly and not match any attribute or key on the `QuerySet` instance.
Original exception text was: 'QuerySet' object has no attribute 'name'.
Traceback (most recent call last):
  File "/home/quang/Desktop/Python/blog-django/venv/lib/python3.8/site-packages/rest_framework/fields.py", line 457, in get_attribute
    return get_attribute(instance, self.source_attrs)
  File "/home/quang/Desktop/Python/blog-django/venv/lib/python3.8/site-packages/rest_framework/fields.py", line 97, in get_attribute
    instance = getattr(instance, attr)
AttributeError: 'QuerySet' object has no attribute 'name'

During handling of the above exception, another exception occurred:

Traceback (most recent call last):
  File "/home/quang/Desktop/Python/blog-django/venv/lib/python3.8/site-packages/django/core/handlers/base.py", line 197, in _get_response
    response = wrapped_callback(request, *callback_args, **callback_kwargs)
  File "/usr/lib/python3.8/contextlib.py", line 75, in inner
    return func(*args, **kwds)
  File "/home/quang/Desktop/Python/blog-django/venv/lib/python3.8/site-packages/django/views/decorators/csrf.py", line 54, in wrapped_view
    return view_func(*args, **kwargs)
  File "/home/quang/Desktop/Python/blog-django/venv/lib/python3.8/site-packages/rest_framework/viewsets.py", line 125, in view
    return self.dispatch(request, *args, **kwargs)
  File "/home/quang/Desktop/Python/blog-django/venv/lib/python3.8/site-packages/rest_framework/views.py", line 509, in dispatch
    response = self.handle_exception(exc)
  File "/home/quang/Desktop/Python/blog-django/venv/lib/python3.8/site-packages/rest_framework/views.py", line 469, in handle_exception
    self.raise_uncaught_exception(exc)
  File "/home/quang/Desktop/Python/blog-django/venv/lib/python3.8/site-packages/rest_framework/views.py", line 480, in raise_uncaught_exception
    raise exc
  File "/home/quang/Desktop/Python/blog-django/venv/lib/python3.8/site-packages/rest_framework/views.py", line 506, in dispatch
    response = handler(request, *args, **kwargs)
  File "/home/quang/Desktop/Python/blog-django/apps/api/views/blog_view.py", line 61, in retrieve
    return Response(serializer.data,status=status.HTTP_200_OK)
  File "/home/quang/Desktop/Python/blog-django/venv/lib/python3.8/site-packages/rest_framework/serializers.py", line 555, in data
    ret = super().data
  File "/home/quang/Desktop/Python/blog-django/venv/lib/python3.8/site-packages/rest_framework/serializers.py", line 253, in data
    self._data = self.to_representation(self.instance)
  File "/home/quang/Desktop/Python/blog-django/venv/lib/python3.8/site-packages/rest_framework/serializers.py", line 509, in to_representation
    attribute = field.get_attribute(instance)
  File "/home/quang/Desktop/Python/blog-django/venv/lib/python3.8/site-packages/rest_framework/fields.py", line 490, in get_attribute
    raise type(exc)(msg)
AttributeError: Got AttributeError when attempting to get a value for field `name` on serializer `PostSerializer`.
The serializer field might be named incorrectly and not match any attribute or key on the `QuerySet` instance.
Original exception text was: 'QuerySet' object has no attribute 'name'.
2022-08-19 09:42:03 ERROR Got AttributeError when attempting to get a value for field `category` on serializer `PostSerializer`.
The serializer field might be named incorrectly and not match any attribute or key on the `QuerySet` instance.
Original exception text was: 'QuerySet' object has no attribute 'category'.
Traceback (most recent call last):
  File "/home/quang/Desktop/Python/blog-django/venv/lib/python3.8/site-packages/rest_framework/fields.py", line 457, in get_attribute
    return get_attribute(instance, self.source_attrs)
  File "/home/quang/Desktop/Python/blog-django/venv/lib/python3.8/site-packages/rest_framework/fields.py", line 97, in get_attribute
    instance = getattr(instance, attr)
AttributeError: 'QuerySet' object has no attribute 'category'

During handling of the above exception, another exception occurred:

Traceback (most recent call last):
  File "/home/quang/Desktop/Python/blog-django/venv/lib/python3.8/site-packages/django/core/handlers/base.py", line 197, in _get_response
    response = wrapped_callback(request, *callback_args, **callback_kwargs)
  File "/usr/lib/python3.8/contextlib.py", line 75, in inner
    return func(*args, **kwds)
  File "/home/quang/Desktop/Python/blog-django/venv/lib/python3.8/site-packages/django/views/decorators/csrf.py", line 54, in wrapped_view
    return view_func(*args, **kwargs)
  File "/home/quang/Desktop/Python/blog-django/venv/lib/python3.8/site-packages/rest_framework/viewsets.py", line 125, in view
    return self.dispatch(request, *args, **kwargs)
  File "/home/quang/Desktop/Python/blog-django/venv/lib/python3.8/site-packages/rest_framework/views.py", line 509, in dispatch
    response = self.handle_exception(exc)
  File "/home/quang/Desktop/Python/blog-django/venv/lib/python3.8/site-packages/rest_framework/views.py", line 469, in handle_exception
    self.raise_uncaught_exception(exc)
  File "/home/quang/Desktop/Python/blog-django/venv/lib/python3.8/site-packages/rest_framework/views.py", line 480, in raise_uncaught_exception
    raise exc
  File "/home/quang/Desktop/Python/blog-django/venv/lib/python3.8/site-packages/rest_framework/views.py", line 506, in dispatch
    response = handler(request, *args, **kwargs)
  File "/home/quang/Desktop/Python/blog-django/apps/api/views/blog_view.py", line 61, in retrieve
    return Response(serializer.data,status=status.HTTP_200_OK)
  File "/home/quang/Desktop/Python/blog-django/venv/lib/python3.8/site-packages/rest_framework/serializers.py", line 555, in data
    ret = super().data
  File "/home/quang/Desktop/Python/blog-django/venv/lib/python3.8/site-packages/rest_framework/serializers.py", line 253, in data
    self._data = self.to_representation(self.instance)
  File "/home/quang/Desktop/Python/blog-django/venv/lib/python3.8/site-packages/rest_framework/serializers.py", line 509, in to_representation
    attribute = field.get_attribute(instance)
  File "/home/quang/Desktop/Python/blog-django/venv/lib/python3.8/site-packages/rest_framework/fields.py", line 490, in get_attribute
    raise type(exc)(msg)
AttributeError: Got AttributeError when attempting to get a value for field `category` on serializer `PostSerializer`.
The serializer field might be named incorrectly and not match any attribute or key on the `QuerySet` instance.
Original exception text was: 'QuerySet' object has no attribute 'category'.
2022-08-19 09:42:32 ERROR Got AttributeError when attempting to get a value for field `category` on serializer `PostSerializer`.
The serializer field might be named incorrectly and not match any attribute or key on the `QuerySet` instance.
Original exception text was: 'QuerySet' object has no attribute 'category'.
Traceback (most recent call last):
  File "/home/quang/Desktop/Python/blog-django/venv/lib/python3.8/site-packages/rest_framework/fields.py", line 457, in get_attribute
    return get_attribute(instance, self.source_attrs)
  File "/home/quang/Desktop/Python/blog-django/venv/lib/python3.8/site-packages/rest_framework/fields.py", line 97, in get_attribute
    instance = getattr(instance, attr)
AttributeError: 'QuerySet' object has no attribute 'category'

During handling of the above exception, another exception occurred:

Traceback (most recent call last):
  File "/home/quang/Desktop/Python/blog-django/venv/lib/python3.8/site-packages/django/core/handlers/base.py", line 197, in _get_response
    response = wrapped_callback(request, *callback_args, **callback_kwargs)
  File "/usr/lib/python3.8/contextlib.py", line 75, in inner
    return func(*args, **kwds)
  File "/home/quang/Desktop/Python/blog-django/venv/lib/python3.8/site-packages/django/views/decorators/csrf.py", line 54, in wrapped_view
    return view_func(*args, **kwargs)
  File "/home/quang/Desktop/Python/blog-django/venv/lib/python3.8/site-packages/rest_framework/viewsets.py", line 125, in view
    return self.dispatch(request, *args, **kwargs)
  File "/home/quang/Desktop/Python/blog-django/venv/lib/python3.8/site-packages/rest_framework/views.py", line 509, in dispatch
    response = self.handle_exception(exc)
  File "/home/quang/Desktop/Python/blog-django/venv/lib/python3.8/site-packages/rest_framework/views.py", line 469, in handle_exception
    self.raise_uncaught_exception(exc)
  File "/home/quang/Desktop/Python/blog-django/venv/lib/python3.8/site-packages/rest_framework/views.py", line 480, in raise_uncaught_exception
    raise exc
  File "/home/quang/Desktop/Python/blog-django/venv/lib/python3.8/site-packages/rest_framework/views.py", line 506, in dispatch
    response = handler(request, *args, **kwargs)
  File "/home/quang/Desktop/Python/blog-django/apps/api/views/blog_view.py", line 61, in retrieve
    return Response(serializer.data,status=status.HTTP_200_OK)
  File "/home/quang/Desktop/Python/blog-django/venv/lib/python3.8/site-packages/rest_framework/serializers.py", line 555, in data
    ret = super().data
  File "/home/quang/Desktop/Python/blog-django/venv/lib/python3.8/site-packages/rest_framework/serializers.py", line 253, in data
    self._data = self.to_representation(self.instance)
  File "/home/quang/Desktop/Python/blog-django/venv/lib/python3.8/site-packages/rest_framework/serializers.py", line 509, in to_representation
    attribute = field.get_attribute(instance)
  File "/home/quang/Desktop/Python/blog-django/venv/lib/python3.8/site-packages/rest_framework/fields.py", line 490, in get_attribute
    raise type(exc)(msg)
AttributeError: Got AttributeError when attempting to get a value for field `category` on serializer `PostSerializer`.
The serializer field might be named incorrectly and not match any attribute or key on the `QuerySet` instance.
Original exception text was: 'QuerySet' object has no attribute 'category'.
2022-08-19 09:47:32 ERROR Got AttributeError when attempting to get a value for field `category` on serializer `PostSerializer`.
The serializer field might be named incorrectly and not match any attribute or key on the `Category` instance.
Original exception text was: 'Category' object has no attribute 'category'.
Traceback (most recent call last):
  File "/home/quang/Desktop/Python/blog-django/venv/lib/python3.8/site-packages/rest_framework/fields.py", line 457, in get_attribute
    return get_attribute(instance, self.source_attrs)
  File "/home/quang/Desktop/Python/blog-django/venv/lib/python3.8/site-packages/rest_framework/fields.py", line 97, in get_attribute
    instance = getattr(instance, attr)
AttributeError: 'Category' object has no attribute 'category'

During handling of the above exception, another exception occurred:

Traceback (most recent call last):
  File "/home/quang/Desktop/Python/blog-django/venv/lib/python3.8/site-packages/django/core/handlers/base.py", line 197, in _get_response
    response = wrapped_callback(request, *callback_args, **callback_kwargs)
  File "/usr/lib/python3.8/contextlib.py", line 75, in inner
    return func(*args, **kwds)
  File "/home/quang/Desktop/Python/blog-django/venv/lib/python3.8/site-packages/django/views/decorators/csrf.py", line 54, in wrapped_view
    return view_func(*args, **kwargs)
  File "/home/quang/Desktop/Python/blog-django/venv/lib/python3.8/site-packages/rest_framework/viewsets.py", line 125, in view
    return self.dispatch(request, *args, **kwargs)
  File "/home/quang/Desktop/Python/blog-django/venv/lib/python3.8/site-packages/rest_framework/views.py", line 509, in dispatch
    response = self.handle_exception(exc)
  File "/home/quang/Desktop/Python/blog-django/venv/lib/python3.8/site-packages/rest_framework/views.py", line 469, in handle_exception
    self.raise_uncaught_exception(exc)
  File "/home/quang/Desktop/Python/blog-django/venv/lib/python3.8/site-packages/rest_framework/views.py", line 480, in raise_uncaught_exception
    raise exc
  File "/home/quang/Desktop/Python/blog-django/venv/lib/python3.8/site-packages/rest_framework/views.py", line 506, in dispatch
    response = handler(request, *args, **kwargs)
  File "/home/quang/Desktop/Python/blog-django/apps/api/views/blog_view.py", line 68, in retrieve
    return Response(serializer.data, status=status.HTTP_200_OK)
  File "/home/quang/Desktop/Python/blog-django/venv/lib/python3.8/site-packages/rest_framework/serializers.py", line 555, in data
    ret = super().data
  File "/home/quang/Desktop/Python/blog-django/venv/lib/python3.8/site-packages/rest_framework/serializers.py", line 253, in data
    self._data = self.to_representation(self.instance)
  File "/home/quang/Desktop/Python/blog-django/venv/lib/python3.8/site-packages/rest_framework/serializers.py", line 509, in to_representation
    attribute = field.get_attribute(instance)
  File "/home/quang/Desktop/Python/blog-django/venv/lib/python3.8/site-packages/rest_framework/fields.py", line 490, in get_attribute
    raise type(exc)(msg)
AttributeError: Got AttributeError when attempting to get a value for field `category` on serializer `PostSerializer`.
The serializer field might be named incorrectly and not match any attribute or key on the `Category` instance.
Original exception text was: 'Category' object has no attribute 'category'.
2022-08-19 10:10:57 ERROR Post matching query does not exist.
Traceback (most recent call last):
  File "/home/quang/Desktop/Python/blog-django/venv/lib/python3.8/site-packages/django/core/handlers/base.py", line 197, in _get_response
    response = wrapped_callback(request, *callback_args, **callback_kwargs)
  File "/usr/lib/python3.8/contextlib.py", line 75, in inner
    return func(*args, **kwds)
  File "/home/quang/Desktop/Python/blog-django/venv/lib/python3.8/site-packages/django/views/decorators/csrf.py", line 54, in wrapped_view
    return view_func(*args, **kwargs)
  File "/home/quang/Desktop/Python/blog-django/venv/lib/python3.8/site-packages/rest_framework/viewsets.py", line 125, in view
    return self.dispatch(request, *args, **kwargs)
  File "/home/quang/Desktop/Python/blog-django/venv/lib/python3.8/site-packages/rest_framework/views.py", line 509, in dispatch
    response = self.handle_exception(exc)
  File "/home/quang/Desktop/Python/blog-django/venv/lib/python3.8/site-packages/rest_framework/views.py", line 469, in handle_exception
    self.raise_uncaught_exception(exc)
  File "/home/quang/Desktop/Python/blog-django/venv/lib/python3.8/site-packages/rest_framework/views.py", line 480, in raise_uncaught_exception
    raise exc
  File "/home/quang/Desktop/Python/blog-django/venv/lib/python3.8/site-packages/rest_framework/views.py", line 506, in dispatch
    response = handler(request, *args, **kwargs)
  File "/home/quang/Desktop/Python/blog-django/apps/api/views/blog_view.py", line 69, in retrieve
    post = Post.objects.get(slug__exact=slug, is_active=True)
  File "/home/quang/Desktop/Python/blog-django/venv/lib/python3.8/site-packages/django/db/models/manager.py", line 85, in manager_method
    return getattr(self.get_queryset(), name)(*args, **kwargs)
  File "/home/quang/Desktop/Python/blog-django/venv/lib/python3.8/site-packages/django/db/models/query.py", line 650, in get
    raise self.model.DoesNotExist(
apps.api.models.blog_model.Post.DoesNotExist: Post matching query does not exist.
2022-08-19 10:11:13 ERROR Post matching query does not exist.
Traceback (most recent call last):
  File "/home/quang/Desktop/Python/blog-django/venv/lib/python3.8/site-packages/django/core/handlers/base.py", line 197, in _get_response
    response = wrapped_callback(request, *callback_args, **callback_kwargs)
  File "/usr/lib/python3.8/contextlib.py", line 75, in inner
    return func(*args, **kwds)
  File "/home/quang/Desktop/Python/blog-django/venv/lib/python3.8/site-packages/django/views/decorators/csrf.py", line 54, in wrapped_view
    return view_func(*args, **kwargs)
  File "/home/quang/Desktop/Python/blog-django/venv/lib/python3.8/site-packages/rest_framework/viewsets.py", line 125, in view
    return self.dispatch(request, *args, **kwargs)
  File "/home/quang/Desktop/Python/blog-django/venv/lib/python3.8/site-packages/rest_framework/views.py", line 509, in dispatch
    response = self.handle_exception(exc)
  File "/home/quang/Desktop/Python/blog-django/venv/lib/python3.8/site-packages/rest_framework/views.py", line 469, in handle_exception
    self.raise_uncaught_exception(exc)
  File "/home/quang/Desktop/Python/blog-django/venv/lib/python3.8/site-packages/rest_framework/views.py", line 480, in raise_uncaught_exception
    raise exc
  File "/home/quang/Desktop/Python/blog-django/venv/lib/python3.8/site-packages/rest_framework/views.py", line 506, in dispatch
    response = handler(request, *args, **kwargs)
  File "/home/quang/Desktop/Python/blog-django/apps/api/views/blog_view.py", line 70, in retrieve
    post = Post.objects.get(slug__exact=slug, is_active=True)
  File "/home/quang/Desktop/Python/blog-django/venv/lib/python3.8/site-packages/django/db/models/manager.py", line 85, in manager_method
    return getattr(self.get_queryset(), name)(*args, **kwargs)
  File "/home/quang/Desktop/Python/blog-django/venv/lib/python3.8/site-packages/django/db/models/query.py", line 650, in get
    raise self.model.DoesNotExist(
apps.api.models.blog_model.Post.DoesNotExist: Post matching query does not exist.
2022-08-19 10:11:54 ERROR Post matching query does not exist.
Traceback (most recent call last):
  File "/home/quang/Desktop/Python/blog-django/venv/lib/python3.8/site-packages/django/core/handlers/base.py", line 197, in _get_response
    response = wrapped_callback(request, *callback_args, **callback_kwargs)
  File "/usr/lib/python3.8/contextlib.py", line 75, in inner
    return func(*args, **kwds)
  File "/home/quang/Desktop/Python/blog-django/venv/lib/python3.8/site-packages/django/views/decorators/csrf.py", line 54, in wrapped_view
    return view_func(*args, **kwargs)
  File "/home/quang/Desktop/Python/blog-django/venv/lib/python3.8/site-packages/rest_framework/viewsets.py", line 125, in view
    return self.dispatch(request, *args, **kwargs)
  File "/home/quang/Desktop/Python/blog-django/venv/lib/python3.8/site-packages/rest_framework/views.py", line 509, in dispatch
    response = self.handle_exception(exc)
  File "/home/quang/Desktop/Python/blog-django/venv/lib/python3.8/site-packages/rest_framework/views.py", line 469, in handle_exception
    self.raise_uncaught_exception(exc)
  File "/home/quang/Desktop/Python/blog-django/venv/lib/python3.8/site-packages/rest_framework/views.py", line 480, in raise_uncaught_exception
    raise exc
  File "/home/quang/Desktop/Python/blog-django/venv/lib/python3.8/site-packages/rest_framework/views.py", line 506, in dispatch
    response = handler(request, *args, **kwargs)
  File "/home/quang/Desktop/Python/blog-django/apps/api/views/blog_view.py", line 70, in retrieve
    post = Post.objects.get(slug__exact=slug)
  File "/home/quang/Desktop/Python/blog-django/venv/lib/python3.8/site-packages/django/db/models/manager.py", line 85, in manager_method
    return getattr(self.get_queryset(), name)(*args, **kwargs)
  File "/home/quang/Desktop/Python/blog-django/venv/lib/python3.8/site-packages/django/db/models/query.py", line 650, in get
    raise self.model.DoesNotExist(
apps.api.models.blog_model.Post.DoesNotExist: Post matching query does not exist.
2022-08-19 10:12:10 ERROR Post matching query does not exist.
Traceback (most recent call last):
  File "/home/quang/Desktop/Python/blog-django/venv/lib/python3.8/site-packages/django/core/handlers/base.py", line 197, in _get_response
    response = wrapped_callback(request, *callback_args, **callback_kwargs)
  File "/usr/lib/python3.8/contextlib.py", line 75, in inner
    return func(*args, **kwds)
  File "/home/quang/Desktop/Python/blog-django/venv/lib/python3.8/site-packages/django/views/decorators/csrf.py", line 54, in wrapped_view
    return view_func(*args, **kwargs)
  File "/home/quang/Desktop/Python/blog-django/venv/lib/python3.8/site-packages/rest_framework/viewsets.py", line 125, in view
    return self.dispatch(request, *args, **kwargs)
  File "/home/quang/Desktop/Python/blog-django/venv/lib/python3.8/site-packages/rest_framework/views.py", line 509, in dispatch
    response = self.handle_exception(exc)
  File "/home/quang/Desktop/Python/blog-django/venv/lib/python3.8/site-packages/rest_framework/views.py", line 469, in handle_exception
    self.raise_uncaught_exception(exc)
  File "/home/quang/Desktop/Python/blog-django/venv/lib/python3.8/site-packages/rest_framework/views.py", line 480, in raise_uncaught_exception
    raise exc
  File "/home/quang/Desktop/Python/blog-django/venv/lib/python3.8/site-packages/rest_framework/views.py", line 506, in dispatch
    response = handler(request, *args, **kwargs)
  File "/home/quang/Desktop/Python/blog-django/apps/api/views/blog_view.py", line 70, in retrieve
    post = Post.objects.get(slug__iexact=slug)
  File "/home/quang/Desktop/Python/blog-django/venv/lib/python3.8/site-packages/django/db/models/manager.py", line 85, in manager_method
    return getattr(self.get_queryset(), name)(*args, **kwargs)
  File "/home/quang/Desktop/Python/blog-django/venv/lib/python3.8/site-packages/django/db/models/query.py", line 650, in get
    raise self.model.DoesNotExist(
apps.api.models.blog_model.Post.DoesNotExist: Post matching query does not exist.
2022-08-19 10:13:18 ERROR Got AttributeError when attempting to get a value for field `category` on serializer `PostSerializer`.
The serializer field might be named incorrectly and not match any attribute or key on the `QuerySet` instance.
Original exception text was: 'QuerySet' object has no attribute 'category'.
Traceback (most recent call last):
  File "/home/quang/Desktop/Python/blog-django/venv/lib/python3.8/site-packages/rest_framework/fields.py", line 457, in get_attribute
    return get_attribute(instance, self.source_attrs)
  File "/home/quang/Desktop/Python/blog-django/venv/lib/python3.8/site-packages/rest_framework/fields.py", line 97, in get_attribute
    instance = getattr(instance, attr)
AttributeError: 'QuerySet' object has no attribute 'category'

During handling of the above exception, another exception occurred:

Traceback (most recent call last):
  File "/home/quang/Desktop/Python/blog-django/venv/lib/python3.8/site-packages/django/core/handlers/base.py", line 197, in _get_response
    response = wrapped_callback(request, *callback_args, **callback_kwargs)
  File "/usr/lib/python3.8/contextlib.py", line 75, in inner
    return func(*args, **kwds)
  File "/home/quang/Desktop/Python/blog-django/venv/lib/python3.8/site-packages/django/views/decorators/csrf.py", line 54, in wrapped_view
    return view_func(*args, **kwargs)
  File "/home/quang/Desktop/Python/blog-django/venv/lib/python3.8/site-packages/rest_framework/viewsets.py", line 125, in view
    return self.dispatch(request, *args, **kwargs)
  File "/home/quang/Desktop/Python/blog-django/venv/lib/python3.8/site-packages/rest_framework/views.py", line 509, in dispatch
    response = self.handle_exception(exc)
  File "/home/quang/Desktop/Python/blog-django/venv/lib/python3.8/site-packages/rest_framework/views.py", line 469, in handle_exception
    self.raise_uncaught_exception(exc)
  File "/home/quang/Desktop/Python/blog-django/venv/lib/python3.8/site-packages/rest_framework/views.py", line 480, in raise_uncaught_exception
    raise exc
  File "/home/quang/Desktop/Python/blog-django/venv/lib/python3.8/site-packages/rest_framework/views.py", line 506, in dispatch
    response = handler(request, *args, **kwargs)
  File "/home/quang/Desktop/Python/blog-django/apps/api/views/blog_view.py", line 75, in retrieve
    return Response(serializer.data, status=status.HTTP_200_OK)
  File "/home/quang/Desktop/Python/blog-django/venv/lib/python3.8/site-packages/rest_framework/serializers.py", line 555, in data
    ret = super().data
  File "/home/quang/Desktop/Python/blog-django/venv/lib/python3.8/site-packages/rest_framework/serializers.py", line 253, in data
    self._data = self.to_representation(self.instance)
  File "/home/quang/Desktop/Python/blog-django/venv/lib/python3.8/site-packages/rest_framework/serializers.py", line 509, in to_representation
    attribute = field.get_attribute(instance)
  File "/home/quang/Desktop/Python/blog-django/venv/lib/python3.8/site-packages/rest_framework/fields.py", line 490, in get_attribute
    raise type(exc)(msg)
AttributeError: Got AttributeError when attempting to get a value for field `category` on serializer `PostSerializer`.
The serializer field might be named incorrectly and not match any attribute or key on the `QuerySet` instance.
Original exception text was: 'QuerySet' object has no attribute 'category'.
2022-08-19 10:33:16 ERROR int() argument must be a string, a bytes-like object or a number, not 'NoneType'
Traceback (most recent call last):
  File "/home/quang/Desktop/Python/blog-django/venv/lib/python3.8/site-packages/django/core/handlers/base.py", line 197, in _get_response
    response = wrapped_callback(request, *callback_args, **callback_kwargs)
  File "/usr/lib/python3.8/contextlib.py", line 75, in inner
    return func(*args, **kwds)
  File "/home/quang/Desktop/Python/blog-django/venv/lib/python3.8/site-packages/django/views/decorators/csrf.py", line 54, in wrapped_view
    return view_func(*args, **kwargs)
  File "/home/quang/Desktop/Python/blog-django/venv/lib/python3.8/site-packages/rest_framework/viewsets.py", line 125, in view
    return self.dispatch(request, *args, **kwargs)
  File "/home/quang/Desktop/Python/blog-django/venv/lib/python3.8/site-packages/rest_framework/views.py", line 509, in dispatch
    response = self.handle_exception(exc)
  File "/home/quang/Desktop/Python/blog-django/venv/lib/python3.8/site-packages/rest_framework/views.py", line 469, in handle_exception
    self.raise_uncaught_exception(exc)
  File "/home/quang/Desktop/Python/blog-django/venv/lib/python3.8/site-packages/rest_framework/views.py", line 480, in raise_uncaught_exception
    raise exc
  File "/home/quang/Desktop/Python/blog-django/venv/lib/python3.8/site-packages/rest_framework/views.py", line 506, in dispatch
    response = handler(request, *args, **kwargs)
  File "/home/quang/Desktop/Python/blog-django/apps/api/views/blog_view.py", line 60, in retrieve
    id_post = int(pk)
TypeError: int() argument must be a string, a bytes-like object or a number, not 'NoneType'
2022-08-19 10:34:04 ERROR int() argument must be a string, a bytes-like object or a number, not 'NoneType'
Traceback (most recent call last):
  File "/home/quang/Desktop/Python/blog-django/venv/lib/python3.8/site-packages/django/core/handlers/base.py", line 197, in _get_response
    response = wrapped_callback(request, *callback_args, **callback_kwargs)
  File "/usr/lib/python3.8/contextlib.py", line 75, in inner
    return func(*args, **kwds)
  File "/home/quang/Desktop/Python/blog-django/venv/lib/python3.8/site-packages/django/views/decorators/csrf.py", line 54, in wrapped_view
    return view_func(*args, **kwargs)
  File "/home/quang/Desktop/Python/blog-django/venv/lib/python3.8/site-packages/rest_framework/viewsets.py", line 125, in view
    return self.dispatch(request, *args, **kwargs)
  File "/home/quang/Desktop/Python/blog-django/venv/lib/python3.8/site-packages/rest_framework/views.py", line 509, in dispatch
    response = self.handle_exception(exc)
  File "/home/quang/Desktop/Python/blog-django/venv/lib/python3.8/site-packages/rest_framework/views.py", line 469, in handle_exception
    self.raise_uncaught_exception(exc)
  File "/home/quang/Desktop/Python/blog-django/venv/lib/python3.8/site-packages/rest_framework/views.py", line 480, in raise_uncaught_exception
    raise exc
  File "/home/quang/Desktop/Python/blog-django/venv/lib/python3.8/site-packages/rest_framework/views.py", line 506, in dispatch
    response = handler(request, *args, **kwargs)
  File "/home/quang/Desktop/Python/blog-django/apps/api/views/blog_view.py", line 60, in retrieve
    id_post = int(pk)
TypeError: int() argument must be a string, a bytes-like object or a number, not 'NoneType'
2022-08-19 10:34:18 ERROR int() argument must be a string, a bytes-like object or a number, not 'NoneType'
Traceback (most recent call last):
  File "/home/quang/Desktop/Python/blog-django/venv/lib/python3.8/site-packages/django/core/handlers/base.py", line 197, in _get_response
    response = wrapped_callback(request, *callback_args, **callback_kwargs)
  File "/usr/lib/python3.8/contextlib.py", line 75, in inner
    return func(*args, **kwds)
  File "/home/quang/Desktop/Python/blog-django/venv/lib/python3.8/site-packages/django/views/decorators/csrf.py", line 54, in wrapped_view
    return view_func(*args, **kwargs)
  File "/home/quang/Desktop/Python/blog-django/venv/lib/python3.8/site-packages/rest_framework/viewsets.py", line 125, in view
    return self.dispatch(request, *args, **kwargs)
  File "/home/quang/Desktop/Python/blog-django/venv/lib/python3.8/site-packages/rest_framework/views.py", line 509, in dispatch
    response = self.handle_exception(exc)
  File "/home/quang/Desktop/Python/blog-django/venv/lib/python3.8/site-packages/rest_framework/views.py", line 469, in handle_exception
    self.raise_uncaught_exception(exc)
  File "/home/quang/Desktop/Python/blog-django/venv/lib/python3.8/site-packages/rest_framework/views.py", line 480, in raise_uncaught_exception
    raise exc
  File "/home/quang/Desktop/Python/blog-django/venv/lib/python3.8/site-packages/rest_framework/views.py", line 506, in dispatch
    response = handler(request, *args, **kwargs)
  File "/home/quang/Desktop/Python/blog-django/apps/api/views/blog_view.py", line 60, in retrieve
    id_post = int(pk)
TypeError: int() argument must be a string, a bytes-like object or a number, not 'NoneType'
2022-08-19 10:34:30 ERROR int() argument must be a string, a bytes-like object or a number, not 'NoneType'
Traceback (most recent call last):
  File "/home/quang/Desktop/Python/blog-django/venv/lib/python3.8/site-packages/django/core/handlers/base.py", line 197, in _get_response
    response = wrapped_callback(request, *callback_args, **callback_kwargs)
  File "/usr/lib/python3.8/contextlib.py", line 75, in inner
    return func(*args, **kwds)
  File "/home/quang/Desktop/Python/blog-django/venv/lib/python3.8/site-packages/django/views/decorators/csrf.py", line 54, in wrapped_view
    return view_func(*args, **kwargs)
  File "/home/quang/Desktop/Python/blog-django/venv/lib/python3.8/site-packages/rest_framework/viewsets.py", line 125, in view
    return self.dispatch(request, *args, **kwargs)
  File "/home/quang/Desktop/Python/blog-django/venv/lib/python3.8/site-packages/rest_framework/views.py", line 509, in dispatch
    response = self.handle_exception(exc)
  File "/home/quang/Desktop/Python/blog-django/venv/lib/python3.8/site-packages/rest_framework/views.py", line 469, in handle_exception
    self.raise_uncaught_exception(exc)
  File "/home/quang/Desktop/Python/blog-django/venv/lib/python3.8/site-packages/rest_framework/views.py", line 480, in raise_uncaught_exception
    raise exc
  File "/home/quang/Desktop/Python/blog-django/venv/lib/python3.8/site-packages/rest_framework/views.py", line 506, in dispatch
    response = handler(request, *args, **kwargs)
  File "/home/quang/Desktop/Python/blog-django/apps/api/views/blog_view.py", line 60, in retrieve
    id_post = int(pk)
TypeError: int() argument must be a string, a bytes-like object or a number, not 'NoneType'
